Workbook

Sheet Global_500_run5
A1: Frame | B1: DeltaTime | C1: ParticleCount | D1: ChannelCollisions | E1: SphereCollisions
A2: 1 | B2: 0.02 | C2: 0 | D2: 0 | E2: 0 | I2: Average Delta Total: | J2: =AVERAGE(B:B) -> 0.13805853 | M2: Frame Saturation: | N2: 200 | O2: More
A3: 2 | B3: 0.02 | C3: 8 | D3: 48 | E3: 5 | I3: Average Delta Saturated: | J3: =AVERAGE(B201:B201) -> 0.333333
A4: 3 | B4: 0.035998 | C4: 16 | D4: 112 | E4: 41 | M4: Total Frames: | N4: 200
A5: 4 | B5: 0.011284 | C5: 37 | D5: 572 | E5: 145 | I5: Max Delta Total | J5: =MAX(B:B) -> 0.333333
A6: 5 | B6: 0.007224 | C6: 41 | D6: 164 | E6: 45 | I6: Max Delta Saturated: | J6: =MAX(B201:B201) -> 0.333333 | M6: UnityCeiling: | N6: 132
A7: 6 | B7: 0.008829 | C7: 45 | D7: 180 | E7: 54
A8: 7 | B8: 0.007881 | C8: 49 | D8: 196 | E8: 49 | I8: Min Delta Total | J8: =MIN(B:B) -> 0.004089
A9: 8 | B9: 0.013534 | C9: 54 | D9: 216 | E9: 46 | I9: Min Delta Saturated | J9: =MIN(B201:B201) -> 0.333333
A10: 9 | B10: 0.008606 | C10: 58 | D10: 232 | E10: 66
A11: 10 | B11: 0.007903 | C11: 66 | D11: 512 | E11: 134 | I11: Average Particle Count Saturated: | J11: =AVERAGE(C201:C201) -> 3066
A12: 11 | B12: 0.008236 | C12: 66 | D12: 0 | E12: 0
A13: 12 | B13: 0.007654 | C13: 70 | D13: 280 | E13: 68 | I13: Channel Collisions Saturated: | J13: =AVERAGE(D201:D201) -> 98164
A14: 13 | B14: 0.008328 | C14: 74 | D14: 296 | E14: 67
A15: 14 | B15: 0.007581 | C15: 79 | D15: 316 | E15: 86 | I15: Sphere Collisions Saturated: | J15: =AVERAGE(E201:E201) -> 23916
A16: 15 | B16: 0.008045 | C16: 83 | D16: 332 | E16: 89
A17: 16 | B17: 0.009308 | C17: 87 | D17: 348 | E17: 92
A18: 17 | B18: 0.009584 | C18: 91 | D18: 364 | E18: 88
A19: 18 | B19: 0.007818 | C19: 95 | D19: 380 | E19: 94
A20: 19 | B20: 0.008095 | C20: 99 | D20: 396 | E20: 94
A21: 20 | B21: 0.007646 | C21: 104 | D21: 416 | E21: 117
A22: 21 | B22: 0.008227 | C22: 108 | D22: 432 | E22: 108
A23: 22 | B23: 0.007271 | C23: 112 | D23: 448 | E23: 108
A24: 23 | B24: 0.008088 | C24: 116 | D24: 464 | E24: 125
A25: 24 | B25: 0.007572 | C25: 120 | D25: 480 | E25: 117
A26: 25 | B26: 0.008096 | C26: 124 | D26: 496 | E26: 128
A27: 26 | B27: 0.007424 | C27: 129 | D27: 516 | E27: 137
... A201: 200 | B201: 0.333333 | C201: 3066 | D201: 98164 | E201: 23916

Sheet Global_500_run4
A1: Frame | B1: DeltaTime | C1: ParticleCount | D1: ChannelCollisions | E1: SphereCollisions
A2: 1 | B2: 0.02 | C2: 0 | D2: 0 | E2: 0 | I2: Average Delta Total: | J2: =AVERAGE(B:B) -> 0.13565849 | M2: Frame Saturation: | N2: 200 | O2: More
A3: 2 | B3: 0.02 | C3: 8 | D3: 48 | E3: 5 | I3: Average Delta Saturated: | J3: =AVERAGE(B201:B201) -> 0.333333
A4: 3 | B4: 0.035511 | C4: 16 | D4: 112 | E4: 41 | M4: Total Frames: | N4: 200
A5: 4 | B5: 0.01032 | C5: 37 | D5: 572 | E5: 145 | I5: Max Delta Total | J5: =MAX(B:B) -> 0.333333
A6: 5 | B6: 0.007462 | C6: 41 | D6: 164 | E6: 45 | I6: Max Delta Saturated: | J6: =MAX(B201:B201) -> 0.333333 | M6: UnityCeiling: | N6: 134
A7: 6 | B7: 0.008813 | C7: 45 | D7: 180 | E7: 54
A8: 7 | B8: 0.008409 | C8: 49 | D8: 196 | E8: 49 | I8: Min Delta Total | J8: =MIN(B:B) -> 0.004161
A9: 8 | B9: 0.00874 | C9: 54 | D9: 216 | E9: 46 | I9: Min Delta Saturated | J9: =MIN(B201:B201) -> 0.333333
A10: 9 | B10: 0.008523 | C10: 58 | D10: 232 | E10: 66
A11: 10 | B11: 0.007544 | C11: 62 | D11: 248 | E11: 69 | I11: Average Particle Count Saturated: | J11: =AVERAGE(C201:C201) -> 3061
A12: 11 | B12: 0.008148 | C12: 66 | D12: 264 | E12: 65
A13: 12 | B13: 0.007562 | C13: 70 | D13: 280 | E13: 68 | I13: Channel Collisions Saturated: | J13: =AVERAGE(D201:D201) -> 98076
A14: 13 | B14: 0.008247 | C14: 74 | D14: 296 | E14: 67
A15: 14 | B15: 0.007553 | C15: 79 | D15: 316 | E15: 86 | I15: Sphere Collisions Saturated: | J15: =AVERAGE(E201:E201) -> 23900
A16: 15 | B16: 0.007957 | C16: 83 | D16: 332 | E16: 89
A17: 16 | B17: 0.007611 | C17: 83 | D17: 0 | E17: 0
A18: 17 | B18: 0.009254 | C18: 87 | D18: 348 | E18: 92
A19: 18 | B19: 0.00761 | C19: 91 | D19: 364 | E19: 88
A20: 19 | B20: 0.006544 | C20: 95 | D20: 380 | E20: 94
A21: 20 | B21: 0.005674 | C21: 99 | D21: 396 | E21: 94
A22: 21 | B22: 0.006052 | C22: 104 | D22: 416 | E22: 117
A23: 22 | B23: 0.006281 | C23: 108 | D23: 432 | E23: 108
A24: 23 | B24: 0.005868 | C24: 108 | D24: 0 | E24: 0
A25: 24 | B25: 0.005876 | C25: 112 | D25: 448 | E25: 108
A26: 25 | B26: 0.006346 | C26: 116 | D26: 464 | E26: 125
A27: 26 | B27: 0.005904 | C27: 120 | D27: 480 | E27: 117
... A201: 200 | B201: 0.333333 | C201: 3061 | D201: 98076 | E201: 23900

Sheet Global_500_run3
A1: Frame | B1: DeltaTime | C1: ParticleCount | D1: ChannelCollisions | E1: SphereCollisions
A2: 1 | B2: 0.02 | C2: 0 | D2: 0 | E2: 0 | I2: Average Delta Total: | J2: =AVERAGE(B:B) -> 0.1476393 | M2: Frame Saturation: | N2: 200 | O2: More
A3: 2 | B3: 0.02 | C3: 8 | D3: 48 | E3: 5 | I3: Average Delta Saturated: | J3: =AVERAGE(B201:B201) -> 0.333333
A4: 3 | B4: 0.03524 | C4: 16 | D4: 112 | E4: 41 | M4: Total Frames: | N4: 200
A5: 4 | B5: 0.010381 | C5: 37 | D5: 572 | E5: 145 | I5: Max Delta Total | J5: =MAX(B:B) -> 0.333333
A6: 5 | B6: 0.006934 | C6: 41 | D6: 164 | E6: 45 | I6: Max Delta Saturated: | J6: =MAX(B201:B201) -> 0.333333 | M6: UnityCeiling: | N6: 127
A7: 6 | B7: 0.012869 | C7: 45 | D7: 180 | E7: 54
A8: 7 | B8: 0.008017 | C8: 49 | D8: 196 | E8: 49 | I8: Min Delta Total | J8: =MIN(B:B) -> 0.004221
A9: 8 | B9: 0.012047 | C9: 54 | D9: 216 | E9: 46 | I9: Min Delta Saturated | J9: =MIN(B201:B201) -> 0.333333
A10: 9 | B10: 0.008662 | C10: 62 | D10: 480 | E10: 135
A11: 10 | B11: 0.007755 | C11: 66 | D11: 264 | E11: 65 | I11: Average Particle Count Saturated: | J11: =AVERAGE(C201:C201) -> 3078
A12: 11 | B12: 0.00837 | C12: 70 | D12: 280 | E12: 68
A13: 12 | B13: 0.007616 | C13: 74 | D13: 296 | E13: 67 | I13: Channel Collisions Saturated: | J13: =AVERAGE(D201:D201) -> 98612
A14: 13 | B14: 0.007891 | C14: 74 | D14: 0 | E14: 0
A15: 14 | B15: 0.007632 | C15: 79 | D15: 316 | E15: 86 | I15: Sphere Collisions Saturated: | J15: =AVERAGE(E201:E201) -> 24400
A16: 15 | B16: 0.008222 | C16: 83 | D16: 332 | E16: 89
A17: 16 | B17: 0.009662 | C17: 87 | D17: 348 | E17: 92
A18: 17 | B18: 0.009785 | C18: 91 | D18: 364 | E18: 88
A19: 18 | B19: 0.007593 | C19: 99 | D19: 776 | E19: 188
A20: 19 | B20: 0.008429 | C20: 104 | D20: 416 | E20: 117
A21: 20 | B21: 0.007504 | C21: 108 | D21: 432 | E21: 108
A22: 21 | B22: 0.008404 | C22: 108 | D22: 0 | E22: 0
A23: 22 | B23: 0.007621 | C23: 112 | D23: 448 | E23: 108
A24: 23 | B24: 0.008483 | C24: 116 | D24: 464 | E24: 125
A25: 24 | B25: 0.007471 | C25: 120 | D25: 480 | E25: 117
A26: 25 | B26: 0.008228 | C26: 124 | D26: 496 | E26: 128
A27: 26 | B27: 0.0077 | C27: 129 | D27: 516 | E27: 137
... A201: 200 | B201: 0.333333 | C201: 3078 | D201: 98612 | E201: 24400

Sheet Global_500_run2
A1: Frame | B1: DeltaTime | C1: ParticleCount | D1: ChannelCollisions | E1: SphereCollisions
A2: 1 | B2: 0.02 | C2: 0 | D2: 0 | E2: 0 | I2: Average Delta Total: | J2: =AVERAGE(B:B) -> 0.15029041 | M2: Frame Saturation: | N2: 200 | O2: More
A3: 2 | B3: 0.02 | C3: 8 | D3: 48 | E3: 5 | I3: Average Delta Saturated: | J3: =AVERAGE(B201:B201) -> 0.333333
A4: 3 | B4: 0.042928 | C4: 16 | D4: 112 | E4: 41 | M4: Total Frames: | N4: 200
A5: 4 | B5: 0.010212 | C5: 37 | D5: 572 | E5: 145 | I5: Max Delta Total | J5: =MAX(B:B) -> 0.333333
A6: 5 | B6: 0.007707 | C6: 45 | D6: 344 | E6: 99 | I6: Max Delta Saturated: | J6: =MAX(B201:B201) -> 0.333333 | M6: UnityCeiling: | N6: 125
A7: 6 | B7: 0.010968 | C7: 49 | D7: 196 | E7: 49
A8: 7 | B8: 0.008083 | C8: 54 | D8: 216 | E8: 46 | I8: Min Delta Total | J8: =MIN(B:B) -> 0.004189
A9: 8 | B9: 0.008964 | C9: 58 | D9: 232 | E9: 66 | I9: Min Delta Saturated | J9: =MIN(B201:B201) -> 0.333333
A10: 9 | B10: 0.008133 | C10: 62 | D10: 248 | E10: 69
A11: 10 | B11: 0.007368 | C11: 66 | D11: 264 | E11: 65 | I11: Average Particle Count Saturated: | J11: =AVERAGE(C201:C201) -> 3080
A12: 11 | B12: 0.008002 | C12: 70 | D12: 280 | E12: 68
A13: 12 | B13: 0.008385 | C13: 74 | D13: 296 | E13: 67 | I13: Channel Collisions Saturated: | J13: =AVERAGE(D201:D201) -> 98680
A14: 13 | B14: 0.008292 | C14: 79 | D14: 316 | E14: 86
A15: 14 | B15: 0.007535 | C15: 83 | D15: 332 | E15: 89 | I15: Sphere Collisions Saturated: | J15: =AVERAGE(E201:E201) -> 24139
A16: 15 | B16: 0.008018 | C16: 87 | D16: 348 | E16: 92
A17: 16 | B17: 0.008491 | C17: 91 | D17: 364 | E17: 88
A18: 17 | B18: 0.009792 | C18: 95 | D18: 380 | E18: 94
A19: 18 | B19: 0.007599 | C19: 99 | D19: 396 | E19: 94
A20: 19 | B20: 0.00789 | C20: 104 | D20: 416 | E20: 117
A21: 20 | B21: 0.00764 | C21: 108 | D21: 432 | E21: 108
A22: 21 | B22: 0.008178 | C22: 112 | D22: 448 | E22: 108
A23: 22 | B23: 0.00757 | C23: 116 | D23: 464 | E23: 125
A24: 23 | B24: 0.007569 | C24: 120 | D24: 480 | E24: 117
A25: 24 | B25: 0.008333 | C25: 120 | D25: 0 | E25: 0
A26: 25 | B26: 0.007642 | C26: 124 | D26: 496 | E26: 128
A27: 26 | B27: 0.008153 | C27: 129 | D27: 516 | E27: 137
... A201: 200 | B201: 0.333333 | C201: 3080 | D201: 98680 | E201: 24139

Sheet Global_500_run1
A1: Frame | B1: DeltaTime | C1: ParticleCount | D1: ChannelCollisions | E1: SphereCollisions
A2: 1 | B2: 0.02 | C2: 0 | D2: 0 | E2: 0 | I2: Average Delta Total: | J2: =AVERAGE(B:B) -> 0.14556141 | M2: Frame Saturation: | N2: 200 | O2: More
A3: 2 | B3: 0.02 | C3: 8 | D3: 48 | E3: 5 | I3: Average Delta Saturated: | J3: =AVERAGE(B201:B201) -> 0.333333
A4: 3 | B4: 0.049479 | C4: 16 | D4: 112 | E4: 41 | M4: Total Frames: | N4: 200
A5: 4 | B5: 0.008857 | C5: 41 | D5: 736 | E5: 190 | I5: Max Delta Total | J5: =MAX(B:B) -> 0.333333
A6: 5 | B6: 0.006957 | C6: 45 | D6: 180 | E6: 54 | I6: Max Delta Saturated: | J6: =MAX(B201:B201) -> 0.333333 | M6: UnityCeiling: | N6: 128
A7: 6 | B7: 0.009509 | C7: 49 | D7: 196 | E7: 49
A8: 7 | B8: 0.007807 | C8: 54 | D8: 216 | E8: 46 | I8: Min Delta Total | J8: =MIN(B:B) -> 0.004195
A9: 8 | B9: 0.010561 | C9: 58 | D9: 232 | E9: 66 | I9: Min Delta Saturated | J9: =MIN(B201:B201) -> 0.333333
A10: 9 | B10: 0.007584 | C10: 62 | D10: 248 | E10: 69
A11: 10 | B11: 0.007638 | C11: 66 | D11: 264 | E11: 65 | I11: Average Particle Count Saturated: | J11: =AVERAGE(C201:C201) -> 3076
A12: 11 | B12: 0.007684 | C12: 70 | D12: 280 | E12: 68
A13: 12 | B13: 0.008585 | C13: 74 | D13: 296 | E13: 67 | I13: Channel Collisions Saturated: | J13: =AVERAGE(D201:D201) -> 98520
A14: 13 | B14: 0.007968 | C14: 79 | D14: 316 | E14: 86
A15: 14 | B15: 0.007524 | C15: 83 | D15: 332 | E15: 89 | I15: Sphere Collisions Saturated: | J15: =AVERAGE(E201:E201) -> 24328
A16: 15 | B16: 0.009451 | C16: 87 | D16: 348 | E16: 92
A17: 16 | B17: 0.010294 | C17: 91 | D17: 364 | E17: 88
A18: 17 | B18: 0.007546 | C18: 95 | D18: 380 | E18: 94
A19: 18 | B19: 0.007592 | C19: 99 | D19: 396 | E19: 94
A20: 19 | B20: 0.00805 | C20: 104 | D20: 416 | E20: 117
A21: 20 | B21: 0.008153 | C21: 108 | D21: 432 | E21: 108
A22: 21 | B22: 0.007848 | C22: 112 | D22: 448 | E22: 108
A23: 22 | B23: 0.00761 | C23: 116 | D23: 464 | E23: 125
A24: 23 | B24: 0.008161 | C24: 120 | D24: 480 | E24: 117
A25: 24 | B25: 0.007424 | C25: 124 | D25: 496 | E25: 128
A26: 25 | B26: 0.008027 | C26: 129 | D26: 516 | E26: 137
A27: 26 | B27: 0.007555 | C27: 133 | D27: 532 | E27: 166
... A201: 200 | B201: 0.333333 | C201: 3076 | D201: 98520 | E201: 24328

Sheet Global_300_run5
A1: Frame | B1: DeltaTime | C1: ParticleCount | D1: ChannelCollisions | E1: SphereCollisions
A2: 1 | B2: 0.02 | C2: 0 | D2: 0 | E2: 0 | I2: Average Delta Total: | J2: =AVERAGE(B:B) -> 0.16860107 | M2: Frame Saturation: | N2: 295
A3: 2 | B3: 0.02 | C3: 5 | D3: 28 | E3: 3 | I3: Average Delta Saturated: | J3: =AVERAGE(B296:B401) -> 0.333333
A4: 3 | B4: 0.046915 | C4: 10 | D4: 68 | E4: 13 | M4: Total Frames: | N4: 400
A5: 4 | B5: 0.008567 | C5: 25 | D5: 444 | E5: 90 | I5: Max Delta Total | J5: =MAX(B:B) -> 0.333333
A6: 5 | B6: 0.006506 | C6: 27 | D6: 108 | E6: 14 | I6: Max Delta Saturated: | J6: =MAX(B296:B401) -> 0.333333 | M6: UnityCeiling: | N6: 222
A7: 6 | B7: 0.012915 | C7: 30 | D7: 120 | E7: 25
A8: 7 | B8: 0.007511 | C8: 32 | D8: 128 | E8: 30 | I8: Min Delta Total | J8: =MIN(B:B) -> 0.004104
A9: 8 | B9: 0.013426 | C9: 35 | D9: 140 | E9: 33 | I9: Min Delta Saturated | J9: =MIN(B296:B401) -> 0.333333
A10: 9 | B10: 0.007778 | C10: 40 | D10: 308 | E10: 60
A11: 10 | B11: 0.007514 | C11: 42 | D11: 168 | E11: 39 | I11: Average Particle Count Saturated: | J11: =AVERAGE(C296:C401) -> 1839.5377
A12: 11 | B12: 0.007996 | C12: 45 | D12: 180 | E12: 35
A13: 12 | B13: 0.007557 | C13: 47 | D13: 188 | E13: 29 | I13: Channel Collisions Saturated: | J13: =AVERAGE(D296:D401) -> 58957.472
A14: 13 | B14: 0.007719 | C14: 50 | D14: 200 | E14: 34
A15: 14 | B15: 0.008193 | C15: 50 | D15: 0 | E15: 0 | I15: Sphere Collisions Saturated: | J15: =AVERAGE(E296:E401) -> 11058.708
A16: 15 | B16: 0.009664 | C16: 52 | D16: 208 | E16: 40
A17: 16 | B17: 0.008895 | C17: 57 | D17: 448 | E17: 89
A18: 17 | B18: 0.008081 | C18: 60 | D18: 240 | E18: 55
A19: 18 | B19: 0.007648 | C19: 62 | D19: 248 | E19: 50
A20: 19 | B20: 0.007609 | C20: 65 | D20: 260 | E20: 54
A21: 20 | B21: 0.008266 | C21: 65 | D21: 0 | E21: 0
A22: 21 | B22: 0.007433 | C22: 67 | D22: 268 | E22: 45
A23: 22 | B23: 0.00828 | C23: 70 | D23: 280 | E23: 46
A24: 23 | B24: 0.007625 | C24: 72 | D24: 288 | E24: 55
A25: 24 | B25: 0.008101 | C25: 75 | D25: 300 | E25: 56
A26: 25 | B26: 0.007367 | C26: 77 | D26: 308 | E26: 61
A27: 26 | B27: 0.00785 | C27: 80 | D27: 320 | E27: 63
... A401: 400 | B401: 0.333333 | C401: 1840 | D401: 59012 | E401: 11002

Sheet Global_300_run4
A1: Frame | B1: DeltaTime | C1: ParticleCount | D1: ChannelCollisions | E1: SphereCollisions
A2: 1 | B2: 0.02 | C2: 0 | D2: 0 | E2: 0 | I2: Average Delta Total: | J2: =AVERAGE(B:B) -> 0.16359091 | M2: Frame Saturation: | N2: 290
A3: 2 | B3: 0.02 | C3: 5 | D3: 28 | E3: 3 | I3: Average Delta Saturated: | J3: =AVERAGE(B291:B401) -> 0.333333
A4: 3 | B4: 0.037156 | C4: 10 | D4: 68 | E4: 13 | M4: Total Frames: | N4: 400
A5: 4 | B5: 0.011023 | C5: 22 | D5: 344 | E5: 67 | I5: Max Delta Total | J5: =MAX(B:B) -> 0.333333
A6: 5 | B6: 0.008003 | C6: 25 | D6: 100 | E6: 23 | I6: Max Delta Saturated: | J6: =MAX(B291:B401) -> 0.333333 | M6: UnityCeiling: | N6: 228
A7: 6 | B7: 0.009754 | C7: 27 | D7: 108 | E7: 14
A8: 7 | B8: 0.007748 | C8: 30 | D8: 120 | E8: 25 | I8: Min Delta Total | J8: =MIN(B:B) -> 0.003963
A9: 8 | B9: 0.010317 | C9: 32 | D9: 128 | E9: 30 | I9: Min Delta Saturated | J9: =MIN(B291:B401) -> 0.333333
A10: 9 | B10: 0.008279 | C10: 35 | D10: 140 | E10: 33
A11: 10 | B11: 0.007449 | C11: 37 | D11: 148 | E11: 30 | I11: Average Particle Count Saturated: | J11: =AVERAGE(C291:C401) -> 1840.2432
A12: 11 | B12: 0.008118 | C12: 40 | D12: 160 | E12: 30
A13: 12 | B13: 0.007647 | C13: 42 | D13: 168 | E13: 39 | I13: Channel Collisions Saturated: | J13: =AVERAGE(D291:D401) -> 58959.459
A14: 13 | B14: 0.00804 | C14: 45 | D14: 180 | E14: 35
A15: 14 | B15: 0.007471 | C15: 47 | D15: 188 | E15: 29 | I15: Sphere Collisions Saturated: | J15: =AVERAGE(E291:E401) -> 11083.243
A16: 15 | B16: 0.008003 | C16: 50 | D16: 200 | E16: 34
A17: 16 | B17: 0.007611 | C17: 52 | D17: 208 | E17: 40
A18: 17 | B18: 0.009335 | C18: 55 | D18: 220 | E18: 46
A19: 18 | B19: 0.008893 | C19: 57 | D19: 228 | E19: 43
A20: 19 | B20: 0.008206 | C20: 60 | D20: 240 | E20: 55
A21: 20 | B21: 0.007574 | C21: 62 | D21: 248 | E21: 50
A22: 21 | B22: 0.007819 | C22: 65 | D22: 260 | E22: 54
A23: 22 | B23: 0.007656 | C23: 67 | D23: 268 | E23: 45
A24: 23 | B24: 0.008244 | C24: 70 | D24: 280 | E24: 46
A25: 24 | B25: 0.007521 | C25: 72 | D25: 288 | E25: 55
A26: 25 | B26: 0.008348 | C26: 75 | D26: 300 | E26: 56
A27: 26 | B27: 0.007507 | C27: 77 | D27: 308 | E27: 61
... A401: 400 | B401: 0.333333 | C401: 1839 | D401: 58936 | E401: 11188

Sheet Global_300_run3
A1: Frame | B1: DeltaTime | C1: ParticleCount | D1: ChannelCollisions | E1: SphereCollisions
A2: 1 | B2: 0.02 | C2: 0 | D2: 0 | E2: 0 | I2: Average Delta Total: | J2: =AVERAGE(B:B) -> 0.17409784 | M2: Frame Saturation: | N2: 289
A3: 2 | B3: 0.02 | C3: 5 | D3: 28 | E3: 3 | I3: Average Delta Saturated: | J3: =AVERAGE(B290:B401) -> 0.333333
A4: 3 | B4: 0.036315 | C4: 10 | D4: 68 | E4: 13 | M4: Total Frames: | N4: 400
A5: 4 | B5: 0.012067 | C5: 22 | D5: 344 | E5: 67 | I5: Max Delta Total | J5: =MAX(B:B) -> 0.333333
A6: 5 | B6: 0.051989 | C6: 25 | D6: 100 | E6: 23 | I6: Max Delta Saturated: | J6: =MAX(B290:B401) -> 0.333333 | M6: UnityCeiling: | N6: 215
A7: 6 | B7: 0.006013 | C7: 40 | D7: 804 | E7: 162
A8: 7 | B8: 0.007723 | C8: 42 | D8: 168 | E8: 39 | I8: Min Delta Total | J8: =MIN(B:B) -> 0.004017
A9: 8 | B9: 0.007568 | C9: 45 | D9: 180 | E9: 35 | I9: Min Delta Saturated | J9: =MIN(B290:B401) -> 0.333333
A10: 9 | B10: 0.010032 | C10: 47 | D10: 188 | E10: 29
A11: 10 | B11: 0.00768 | C11: 50 | D11: 200 | E11: 34 | I11: Average Particle Count Saturated: | J11: =AVERAGE(C290:C401) -> 1839.75
A12: 11 | B12: 0.00831 | C12: 52 | D12: 208 | E12: 40
A13: 12 | B13: 0.009043 | C13: 55 | D13: 220 | E13: 46 | I13: Channel Collisions Saturated: | J13: =AVERAGE(D290:D401) -> 58959.071
A14: 13 | B14: 0.00957 | C14: 57 | D14: 228 | E14: 43
A15: 14 | B15: 0.006719 | C15: 60 | D15: 240 | E15: 55 | I15: Sphere Collisions Saturated: | J15: =AVERAGE(E290:E401) -> 11058.598
A16: 15 | B16: 0.007809 | C16: 62 | D16: 248 | E16: 50
A17: 16 | B17: 0.006955 | C17: 65 | D17: 260 | E17: 54
A18: 17 | B18: 0.007218 | C18: 67 | D18: 268 | E18: 45
A19: 18 | B19: 0.007005 | C19: 70 | D19: 280 | E19: 46
A20: 19 | B20: 0.007568 | C20: 72 | D20: 288 | E20: 55
A21: 20 | B21: 0.006926 | C21: 72 | D21: 0 | E21: 0
A22: 21 | B22: 0.007084 | C22: 75 | D22: 300 | E22: 56
A23: 22 | B23: 0.007584 | C23: 77 | D23: 308 | E23: 61
A24: 23 | B24: 0.006875 | C24: 80 | D24: 320 | E24: 63
A25: 24 | B25: 0.007341 | C25: 82 | D25: 328 | E25: 66
A26: 25 | B26: 0.00702 | C26: 85 | D26: 340 | E26: 68
A27: 26 | B27: 0.007336 | C27: 87 | D27: 348 | E27: 57
... A401: 400 | B401: 0.333333 | C401: 1841 | D401: 58996 | E401: 11288

Sheet Global_300_run2
A1: Frame | B1: DeltaTime | C1: ParticleCount | D1: ChannelCollisions | E1: SphereCollisions
A2: 1 | B2: 0.02 | C2: 0 | D2: 0 | E2: 0 | I2: Average Delta Total: | J2: =AVERAGE(B:B) -> 0.16369585 | M2: Frame Saturation: | N2: 290
A3: 2 | B3: 0.02 | C3: 5 | D3: 28 | E3: 3 | I3: Average Delta Saturated: | J3: =AVERAGE(B291:B401) -> 0.333333
A4: 3 | B4: 0.037206 | C4: 10 | D4: 68 | E4: 13 | M4: Total Frames: | N4: 400
A5: 4 | B5: 0.017647 | C5: 22 | D5: 344 | E5: 67 | I5: Max Delta Total | J5: =MAX(B:B) -> 0.333333
A6: 5 | B6: 0.007301 | C6: 27 | D6: 208 | E6: 37 | I6: Max Delta Saturated: | J6: =MAX(B291:B401) -> 0.333333 | M6: UnityCeiling: | N6: 228
A7: 6 | B7: 0.012279 | C7: 30 | D7: 120 | E7: 25
A8: 7 | B8: 0.007553 | C8: 32 | D8: 128 | E8: 30 | I8: Min Delta Total | J8: =MIN(B:B) -> 0.004041
A9: 8 | B9: 0.010335 | C9: 35 | D9: 140 | E9: 33 | I9: Min Delta Saturated | J9: =MIN(B291:B401) -> 0.333333
A10: 9 | B10: 0.007585 | C10: 37 | D10: 148 | E10: 30
A11: 10 | B11: 0.008078 | C11: 40 | D11: 160 | E11: 30 | I11: Average Particle Count Saturated: | J11: =AVERAGE(C291:C401) -> 1839.6757
A12: 11 | B12: 0.007729 | C12: 42 | D12: 168 | E12: 39
A13: 12 | B13: 0.008071 | C13: 45 | D13: 180 | E13: 35 | I13: Channel Collisions Saturated: | J13: =AVERAGE(D291:D401) -> 58959.495
A14: 13 | B14: 0.007605 | C14: 47 | D14: 188 | E14: 29
A15: 14 | B15: 0.007866 | C15: 50 | D15: 200 | E15: 34 | I15: Sphere Collisions Saturated: | J15: =AVERAGE(E291:E401) -> 11083.081
A16: 15 | B16: 0.00768 | C16: 52 | D16: 208 | E16: 40
A17: 16 | B17: 0.010022 | C17: 55 | D17: 220 | E17: 46
A18: 17 | B18: 0.009766 | C18: 57 | D18: 228 | E18: 43
A19: 18 | B19: 0.007924 | C19: 60 | D19: 240 | E19: 55
A20: 19 | B20: 0.007768 | C20: 62 | D20: 248 | E20: 50
A21: 20 | B21: 0.008152 | C21: 65 | D21: 260 | E21: 54
A22: 21 | B22: 0.007731 | C22: 67 | D22: 268 | E22: 45
A23: 22 | B23: 0.008077 | C23: 70 | D23: 280 | E23: 46
A24: 23 | B24: 0.007738 | C24: 72 | D24: 288 | E24: 55
A25: 24 | B25: 0.007946 | C25: 75 | D25: 300 | E25: 56
A26: 25 | B26: 0.007612 | C26: 77 | D26: 308 | E26: 61
A27: 26 | B27: 0.008331 | C27: 80 | D27: 320 | E27: 63
... A401: 400 | B401: 0.333333 | C401: 1839 | D401: 58940 | E401: 11156

Sheet Global_300_run1
A1: Frame | B1: DeltaTime | C1: ParticleCount | D1: ChannelCollisions | E1: SphereCollisions
A2: 1 | B2: 0.02 | C2: 0 | D2: 0 | E2: 0 | I2: Average Delta Total: | J2: =AVERAGE(B:B) -> 0.16356831 | M2: Frame Saturation: | N2: 290
A3: 2 | B3: 0.02 | C3: 5 | D3: 28 | E3: 3 | I3: Average Delta Saturated: | J3: =AVERAGE(B291:B401) -> 0.333333
A4: 3 | B4: 0.054145 | C4: 10 | D4: 68 | E4: 13 | M4: Total Frames: | N4: 400
A5: 4 | B5: 0.00857 | C5: 27 | D5: 552 | E5: 104 | I5: Max Delta Total | J5: =MAX(B:B) -> 0.333333
A6: 5 | B6: 0.006705 | C6: 30 | D6: 120 | E6: 25 | I6: Max Delta Saturated: | J6: =MAX(B291:B401) -> 0.333333 | M6: UnityCeiling: | N6: 228
A7: 6 | B7: 0.00975 | C7: 32 | D7: 128 | E7: 30
A8: 7 | B8: 0.007964 | C8: 35 | D8: 140 | E8: 33 | I8: Min Delta Total | J8: =MIN(B:B) -> 0.004003
A9: 8 | B9: 0.011749 | C9: 37 | D9: 148 | E9: 30 | I9: Min Delta Saturated | J9: =MIN(B291:B401) -> 0.333333
A10: 9 | B10: 0.007612 | C10: 40 | D10: 160 | E10: 30
A11: 10 | B11: 0.007984 | C11: 42 | D11: 168 | E11: 39 | I11: Average Particle Count Saturated: | J11: =AVERAGE(C291:C401) -> 1840.3243
A12: 11 | B12: 0.007562 | C12: 45 | D12: 180 | E12: 35
A13: 12 | B13: 0.008179 | C13: 47 | D13: 188 | E13: 29 | I13: Channel Collisions Saturated: | J13: =AVERAGE(D291:D401) -> 58959.387
A14: 13 | B14: 0.007664 | C14: 50 | D14: 200 | E14: 34
A15: 14 | B15: 0.007703 | C15: 52 | D15: 208 | E15: 40 | I15: Sphere Collisions Saturated: | J15: =AVERAGE(E291:E401) -> 11083.117
A16: 15 | B16: 0.010453 | C16: 55 | D16: 220 | E16: 46
A17: 16 | B17: 0.009893 | C17: 57 | D17: 228 | E17: 43
A18: 17 | B18: 0.007555 | C18: 60 | D18: 240 | E18: 55
A19: 18 | B19: 0.007785 | C19: 62 | D19: 248 | E19: 50
A20: 19 | B20: 0.007625 | C20: 65 | D20: 260 | E20: 54
A21: 20 | B21: 0.00816 | C21: 67 | D21: 268 | E21: 45
A22: 21 | B22: 0.005957 | C22: 70 | D22: 280 | E22: 46
A23: 22 | B23: 0.005507 | C23: 72 | D23: 288 | E23: 55
A24: 23 | B24: 0.004858 | C24: 72 | D24: 0 | E24: 0
A25: 24 | B25: 0.005498 | C25: 75 | D25: 300 | E25: 56
A26: 25 | B26: 0.005965 | C26: 77 | D26: 308 | E26: 61
A27: 26 | B27: 0.005312 | C27: 77 | D27: 0 | E27: 0
... A401: 400 | B401: 0.333333 | C401: 1839 | D401: 58940 | E401: 11184

Sheet Global_100_run5
A1: Frame | B1: DeltaTime | C1: ParticleCount | D1: ChannelCollisions | E1: SphereCollisions
A2: 1 | B2: 0.02 | C2: 0 | D2: 0 | E2: 0 | I2: Average Delta Total: | J2: =AVERAGE(B:B) -> 0.066458964 | M2: Frame Saturation: | N2: 630
A3: 2 | B3: 0.02 | C3: 1 | D3: 4 | E3: 0 | I3: Average Delta Saturated: | J3: =AVERAGE(B631:B1601) -> 0.10206415
A4: 3 | B4: 0.054757 | C4: 3 | D4: 20 | E4: 1 | M4: Total Frames: | N4: 1600
A5: 4 | B5: 0.008327 | C5: 9 | D5: 176 | E5: 22 | I5: Max Delta Total | J5: =MAX(B:B) -> 0.108482
A6: 5 | B6: 0.008016 | C6: 10 | D6: 40 | E6: 5 | I6: Max Delta Saturated: | J6: =MAX(B631:B1601) -> 0.108482
A7: 6 | B7: 0.009104 | C7: 10 | D7: 40 | E7: 3
A8: 7 | B8: 0.007584 | C8: 11 | D8: 44 | E8: 3 | I8: Min Delta Total | J8: =MIN(B:B) -> 0.003977
A9: 8 | B9: 0.011135 | C9: 12 | D9: 48 | E9: 5 | I9: Min Delta Saturated | J9: =MIN(B631:B1604) -> 0.098531
A10: 9 | B10: 0.007702 | C10: 13 | D10: 52 | E10: 6
A11: 10 | B11: 0.008316 | C11: 14 | D11: 56 | E11: 4 | I11: Average Particle Count Saturated: | J11: =AVERAGE(C631:C1601) -> 599.42225
A12: 11 | B12: 0.007738 | C12: 15 | D12: 60 | E12: 7
A13: 12 | B13: 0.007721 | C13: 15 | D13: 60 | E13: 6 | I13: Channel Collisions Saturated: | J13: =AVERAGE(D631:D1601) -> 19205.306
A14: 13 | B14: 0.008432 | C14: 16 | D14: 64 | E14: 8
A15: 14 | B15: 0.007951 | C15: 17 | D15: 68 | E15: 6 | I15: Sphere Collisions Saturated: | J15: =AVERAGE(E631:E1601) -> 3100.4387
A16: 15 | B16: 0.009644 | C16: 18 | D16: 72 | E16: 10
A17: 16 | B17: 0.009553 | C17: 19 | D17: 76 | E17: 9
A18: 17 | B18: 0.007688 | C18: 20 | D18: 80 | E18: 9
A19: 18 | B19: 0.00795 | C19: 20 | D19: 80 | E19: 8
A20: 19 | B20: 0.00761 | C20: 21 | D20: 84 | E20: 8
A21: 20 | B21: 0.007899 | C21: 22 | D21: 88 | E21: 7
A22: 21 | B22: 0.007584 | C22: 23 | D22: 92 | E22: 13
A23: 22 | B23: 0.008297 | C23: 24 | D23: 96 | E23: 10
A24: 23 | B24: 0.007546 | C24: 25 | D24: 100 | E24: 11
A25: 24 | B25: 0.007947 | C25: 25 | D25: 100 | E25: 9
A26: 25 | B26: 0.007522 | C26: 26 | D26: 104 | E26: 5
A27: 26 | B27: 0.00812 | C27: 27 | D27: 108 | E27: 8
... A1601: 1600 | B1601: 0.101199 | C1601: 600 | D1601: 19196 | E1601: 3157

Sheet Global_100_run4
A1: Frame | B1: DeltaTime | C1: ParticleCount | D1: ChannelCollisions | E1: SphereCollisions
A2: 1 | B2: 0.02 | C2: 0 | D2: 0 | E2: 0 | I2: Average Delta Total: | J2: =AVERAGE(B:B) -> 0.065708611 | M2: Frame Saturation: | N2: 632
A3: 2 | B3: 0.02 | C3: 1 | D3: 4 | E3: 0 | I3: Average Delta Saturated: | J3: =AVERAGE(B633:B1601) -> 0.10108908
A4: 3 | B4: 0.039362 | C4: 3 | D4: 20 | E4: 1 | M4: Total Frames: | N4: 1600
A5: 4 | B5: 0.008779 | C5: 7 | D5: 108 | E5: 12 | I5: Max Delta Total | J5: =MAX(B:B) -> 0.106196
A6: 5 | B6: 0.00602 | C6: 8 | D6: 32 | E6: 4 | I6: Max Delta Saturated: | J6: =MAX(B633:B1601) -> 0.106196
A7: 6 | B7: 0.009084 | C7: 9 | D7: 36 | E7: 6
A8: 7 | B8: 0.006522 | C8: 10 | D8: 40 | E8: 5 | I8: Min Delta Total | J8: =MIN(B:B) -> 0.003891
A9: 8 | B9: 0.014563 | C9: 10 | D9: 40 | E9: 3 | I9: Min Delta Saturated | J9: =MIN(B633:B1604) -> 0.097176
A10: 9 | B10: 0.006642 | C10: 11 | D10: 44 | E10: 3
A11: 10 | B11: 0.005847 | C11: 12 | D11: 48 | E11: 5 | I11: Average Particle Count Saturated: | J11: =AVERAGE(C633:C1601) -> 599.42105
A12: 11 | B12: 0.006393 | C12: 13 | D12: 52 | E12: 6
A13: 12 | B13: 0.006195 | C13: 14 | D13: 56 | E13: 4 | I13: Channel Collisions Saturated: | J13: =AVERAGE(D633:D1601) -> 19205.263
A14: 13 | B14: 0.011959 | C14: 14 | D14: 0 | E14: 0
A15: 14 | B15: 0.006086 | C15: 15 | D15: 120 | E15: 13 | I15: Sphere Collisions Saturated: | J15: =AVERAGE(E633:E1601) -> 3100.3602
A16: 15 | B16: 0.005948 | C16: 16 | D16: 64 | E16: 8
A17: 16 | B17: 0.006903 | C17: 16 | D17: 0 | E17: 0
A18: 17 | B18: 0.00721 | C18: 17 | D18: 68 | E18: 6
A19: 18 | B19: 0.00766 | C19: 18 | D19: 72 | E19: 10
A20: 19 | B20: 0.005892 | C20: 19 | D20: 76 | E20: 9
A21: 20 | B21: 0.006273 | C21: 20 | D21: 80 | E21: 9
A22: 21 | B22: 0.006462 | C22: 20 | D22: 0 | E22: 0
A23: 22 | B23: 0.006153 | C23: 20 | D23: 80 | E23: 8
A24: 23 | B24: 0.006496 | C24: 21 | D24: 84 | E24: 8
A25: 24 | B25: 0.006168 | C25: 22 | D25: 88 | E25: 7
A26: 25 | B26: 0.006083 | C26: 22 | D26: 0 | E26: 0
A27: 26 | B27: 0.006428 | C27: 23 | D27: 92 | E27: 13
... A1601: 1600 | B1601: 0.100581 | C1601: 600 | D1601: 19168 | E1601: 3015

Sheet Global_100_run3
A1: Frame | B1: DeltaTime | C1: ParticleCount | D1: ChannelCollisions | E1: SphereCollisions
A2: 1 | B2: 0.02 | C2: 0 | D2: 0 | E2: 0 | I2: Average Delta Total: | J2: =AVERAGE(B:B) -> 0.066165488 | M2: Frame Saturation: | N2: 628
A3: 2 | B3: 0.02 | C3: 1 | D3: 4 | E3: 0 | I3: Average Delta Saturated: | J3: =AVERAGE(B629:B1601) -> 0.10166874
A4: 3 | B4: 0.048321 | C4: 3 | D4: 20 | E4: 1 | M4: Total Frames: | N4: 1600
A5: 4 | B5: 0.014137 | C5: 8 | D5: 140 | E5: 16 | I5: Max Delta Total | J5: =MAX(B:B) -> 0.107007
A6: 5 | B6: 0.006709 | C6: 10 | D6: 76 | E6: 11 | I6: Max Delta Saturated: | J6: =MAX(B629:B1601) -> 0.107007
A7: 6 | B7: 0.009717 | C7: 10 | D7: 40 | E7: 3
A8: 7 | B8: 0.007593 | C8: 11 | D8: 44 | E8: 3 | I8: Min Delta Total | J8: =MIN(B:B) -> 0.00391
A9: 8 | B9: 0.0087 | C9: 12 | D9: 48 | E9: 5 | I9: Min Delta Saturated | J9: =MIN(B629:B1604) -> 0.098144
A10: 9 | B10: 0.007656 | C10: 13 | D10: 52 | E10: 6
A11: 10 | B11: 0.008258 | C11: 14 | D11: 56 | E11: 4 | I11: Average Particle Count Saturated: | J11: =AVERAGE(C629:C1601) -> 599.41418
A12: 11 | B12: 0.007428 | C12: 15 | D12: 60 | E12: 7
A13: 12 | B13: 0.008097 | C13: 15 | D13: 60 | E13: 6 | I13: Channel Collisions Saturated: | J13: =AVERAGE(D629:D1601) -> 19205.077
A14: 13 | B14: 0.007884 | C14: 15 | D14: 0 | E14: 0
A15: 14 | B15: 0.007903 | C15: 16 | D15: 64 | E15: 8 | I15: Sphere Collisions Saturated: | J15: =AVERAGE(E629:E1601) -> 3100.3165
A16: 15 | B16: 0.00963 | C16: 17 | D16: 68 | E16: 6
A17: 16 | B17: 0.009207 | C17: 19 | D17: 148 | E17: 19
A18: 17 | B18: 0.007696 | C18: 20 | D18: 80 | E18: 9
A19: 18 | B19: 0.008063 | C19: 20 | D19: 80 | E19: 8
A20: 19 | B20: 0.007227 | C20: 21 | D20: 84 | E20: 8
A21: 20 | B21: 0.005935 | C21: 21 | D21: 0 | E21: 0
A22: 21 | B22: 0.00571 | C22: 22 | D22: 88 | E22: 7
A23: 22 | B23: 0.00552 | C23: 23 | D23: 92 | E23: 13
A24: 23 | B24: 0.00603 | C24: 23 | D24: 0 | E24: 0
A25: 24 | B25: 0.005444 | C25: 24 | D25: 96 | E25: 10
A26: 25 | B26: 0.006481 | C26: 25 | D26: 100 | E26: 11
A27: 26 | B27: 0.005903 | C27: 25 | D27: 100 | E27: 9
... A1601: 1600 | B1601: 0.099307 | C1601: 599 | D1601: 19212 | E1601: 3100

Sheet Global_100_run2
A1: Frame | B1: DeltaTime | C1: ParticleCount | D1: ChannelCollisions | E1: SphereCollisions
A2: 1 | B2: 0.02 | C2: 0 | D2: 0 | E2: 0 | I2: Average Delta Total: | J2: =AVERAGE(B:B) -> 0.067251516 | M2: Frame Saturation: | N2: 623
A3: 2 | B3: 0.02 | C3: 1 | D3: 4 | E3: 0 | I3: Average Delta Saturated: | J3: =AVERAGE(B624:B1601) -> 0.10263106
A4: 3 | B4: 0.036678 | C4: 3 | D4: 20 | E4: 1 | M4: Total Frames: | N4: 1600
A5: 4 | B5: 0.012241 | C5: 7 | D5: 108 | E5: 12 | I5: Max Delta Total | J5: =MAX(B:B) -> 0.110889
A6: 5 | B6: 0.00702 | C6: 8 | D6: 32 | E6: 4 | I6: Max Delta Saturated: | J6: =MAX(B624:B1601) -> 0.110889
A7: 6 | B7: 0.007639 | C7: 9 | D7: 36 | E7: 6
A8: 7 | B8: 0.009061 | C8: 10 | D8: 40 | E8: 5 | I8: Min Delta Total | J8: =MIN(B:B) -> 0.004007
A9: 8 | B9: 0.007606 | C9: 10 | D9: 40 | E9: 3 | I9: Min Delta Saturated | J9: =MIN(B624:B1604) -> 0.0986
A10: 9 | B10: 0.008166 | C10: 11 | D10: 44 | E10: 3
A11: 10 | B11: 0.00739 | C11: 12 | D11: 48 | E11: 5 | I11: Average Particle Count Saturated: | J11: =AVERAGE(C624:C1601) -> 599.42025
A12: 11 | B12: 0.008049 | C12: 13 | D12: 52 | E12: 6
A13: 12 | B13: 0.007787 | C13: 14 | D13: 56 | E13: 4 | I13: Channel Collisions Saturated: | J13: =AVERAGE(D624:D1601) -> 19205.153
A14: 13 | B14: 0.008274 | C14: 15 | D14: 60 | E14: 7
A15: 14 | B15: 0.007734 | C15: 15 | D15: 60 | E15: 6 | I15: Sphere Collisions Saturated: | J15: =AVERAGE(E624:E1601) -> 3100.1554
A16: 15 | B16: 0.008169 | C16: 16 | D16: 64 | E16: 8
A17: 16 | B17: 0.008278 | C17: 17 | D17: 68 | E17: 6
A18: 17 | B18: 0.009347 | C18: 18 | D18: 72 | E18: 10
A19: 18 | B19: 0.009676 | C19: 19 | D19: 76 | E19: 9
A20: 19 | B20: 0.007819 | C20: 20 | D20: 80 | E20: 9
A21: 20 | B21: 0.007643 | C21: 20 | D21: 80 | E21: 8
A22: 21 | B22: 0.008153 | C22: 21 | D22: 84 | E22: 8
A23: 22 | B23: 0.007724 | C23: 22 | D23: 88 | E23: 7
A24: 23 | B24: 0.008352 | C24: 23 | D24: 92 | E24: 13
A25: 24 | B25: 0.007596 | C25: 24 | D25: 96 | E25: 10
A26: 25 | B26: 0.007457 | C26: 25 | D26: 100 | E26: 11
A27: 26 | B27: 0.008011 | C27: 25 | D27: 0 | E27: 0
... A1601: 1600 | B1601: 0.103584 | C1601: 599 | D1601: 19176 | E1601: 3171

Sheet Global_100_run1
A1: Frame | B1: DeltaTime | C1: ParticleCount | D1: ChannelCollisions | E1: SphereCollisions
A2: 1 | B2: 0.02 | C2: 0 | D2: 0 | E2: 0 | I2: Average Delta Total: | J2: =AVERAGE(B:B) -> 0.065930249 | M2: Frame Saturation: | N2: 631
A3: 2 | B3: 0.02 | C3: 1 | D3: 4 | E3: 0 | I3: Average Delta Saturated: | J3: =AVERAGE(B632:B1601) -> 0.10131664
A4: 3 | B4: 0.036402 | C4: 3 | D4: 20 | E4: 1 | M4: Total Frames: | N4: 1600
A5: 4 | B5: 0.010167 | C5: 7 | D5: 108 | E5: 12 | I5: Max Delta Total | J5: =MAX(B:B) -> 0.106843
A6: 5 | B6: 0.006924 | C6: 8 | D6: 32 | E6: 4 | I6: Max Delta Saturated: | J6: =MAX(B632:B1601) -> 0.106843
A7: 6 | B7: 0.011402 | C7: 9 | D7: 36 | E7: 6
A8: 7 | B8: 0.007959 | C8: 10 | D8: 40 | E8: 5 | I8: Min Delta Total | J8: =MIN(B:B) -> 0.003898
A9: 8 | B9: 0.008442 | C9: 10 | D9: 40 | E9: 3 | I9: Min Delta Saturated | J9: =MIN(B632:B1604) -> 0.097852
A10: 9 | B10: 0.007972 | C10: 11 | D10: 44 | E10: 3
A11: 10 | B11: 0.007526 | C11: 12 | D11: 48 | E11: 5 | I11: Average Particle Count Saturated: | J11: =AVERAGE(C632:C1601) -> 599.42371
A12: 11 | B12: 0.007994 | C12: 13 | D12: 52 | E12: 6
A13: 12 | B13: 0.007497 | C13: 14 | D13: 56 | E13: 4 | I13: Channel Collisions Saturated: | J13: =AVERAGE(D632:D1601) -> 19205.295
A14: 13 | B14: 0.008224 | C14: 15 | D14: 60 | E14: 7
A15: 14 | B15: 0.007571 | C15: 15 | D15: 60 | E15: 6 | I15: Sphere Collisions Saturated: | J15: =AVERAGE(E632:E1601) -> 3100.332
A16: 15 | B16: 0.008016 | C16: 16 | D16: 64 | E16: 8
A17: 16 | B17: 0.007567 | C17: 17 | D17: 68 | E17: 6
A18: 17 | B18: 0.009134 | C18: 18 | D18: 72 | E18: 10
A19: 18 | B19: 0.009707 | C19: 19 | D19: 76 | E19: 9
A20: 19 | B20: 0.007845 | C20: 20 | D20: 80 | E20: 9
A21: 20 | B21: 0.007491 | C21: 20 | D21: 80 | E21: 8
A22: 21 | B22: 0.008134 | C22: 21 | D22: 84 | E22: 8
A23: 22 | B23: 0.007493 | C23: 22 | D23: 88 | E23: 7
A24: 23 | B24: 0.007603 | C24: 23 | D24: 92 | E24: 13
A25: 24 | B25: 0.008181 | C25: 23 | D25: 0 | E25: 0
A26: 25 | B26: 0.007292 | C26: 24 | D26: 96 | E26: 10
A27: 26 | B27: 0.008305 | C27: 25 | D27: 100 | E27: 11
... A1601: 1600 | B1601: 0.101947 | C1601: 599 | D1601: 19212 | E1601: 3073

Sheet Batch Data
B2: Particles Per Second | C2: 100 | D2: 300 | E2: 500 | G2: DeltaTime | H2: 100 | I2: 300 | J2: 500 | M2: Sphere Collisions | N2: 100 | O2: 300 | P2: 500
B3: Average DeltaTime Saturated | C3: =AVERAGE(Global_100_run5!J3,Global_100_run4!J3,Global_100_run3!J3,Global_100_run2!J3,Global_100_run1!J3) -> 0.10175393 | D3: =AVERAGE(Global_300_run5!J3,Global_300_run4!J3,Global_300_run3!J3,Global_300_run2!J3,Global_300_run1!J3) -> 0.333333 | E3: =AVERAGE(Global_500_run5!J3,Global_500_run4!J3,Global_500_run3!J3,Global_500_run2!J3,Global_500_run1!J3) -> 0.333333 | H3: =AVERAGE(Global_100_run1!B2,Global_100_run2!B2,Global_100_run3!B2,Global_100_run4!B2,Global_100_run5!B2) -> 0.02 | I3: =AVERAGE(Global_300_run1!B2,Global_300_run2!B2,Global_300_run3!B2,Global_300_run4!B2,Global_300_run5!B2) -> 0.02 | J3: =AVERAGE(Global_500_run1!B2,Global_500_run2!B2,Global_500_run3!B2,Global_500_run4!B2,Global_500_run5!B2) -> 0.02 | N3: =AVERAGE(Global_100_run1!E2,Global_100_run2!E2,Global_100_run3!E2,Global_100_run4!E2,Global_100_run5!E2) -> 0 | O3: =AVERAGE(Global_300_run1!E2,Global_300_run2!E2,Global_300_run3!E2,Global_300_run4!E2,Global_300_run5!E2) -> 0 | P3: =AVERAGE(Global_500_run1!E2,Global_500_run2!E2,Global_500_run3!E2,Global_500_run4!E2,Global_500_run5!E2) -> 0
H4: =AVERAGE(Global_100_run1!B3,Global_100_run2!B3,Global_100_run3!B3,Global_100_run4!B3,Global_100_run5!B3) -> 0.02 | I4: =AVERAGE(Global_300_run1!B3,Global_300_run2!B3,Global_300_run3!B3,Global_300_run4!B3,Global_300_run5!B3) -> 0.02 | J4: =AVERAGE(Global_500_run1!B3,Global_500_run2!B3,Global_500_run3!B3,Global_500_run4!B3,Global_500_run5!B3) -> 0.02 | N4: =AVERAGE(Global_100_run1!E3,Global_100_run2!E3,Global_100_run3!E3,Global_100_run4!E3,Global_100_run5!E3) -> 0 | O4: =AVERAGE(Global_300_run1!E3,Global_300_run2!E3,Global_300_run3!E3,Global_300_run4!E3,Global_300_run5!E3) -> 3 | P4: =AVERAGE(Global_500_run1!E3,Global_500_run2!E3,Global_500_run3!E3,Global_500_run4!E3,Global_500_run5!E3) -> 5
B5: Max Delta Saturated: | C5: =MAX(Global_100_run5!J6,Global_100_run4!J6,Global_100_run3!J6,Global_100_run2!J6,Global_100_run1!J6) -> 0.110889 | D5: =MAX(Global_300_run5!J6,Global_300_run4!J6,Global_300_run3!J6,Global_300_run2!J6,Global_300_run1!J6) -> 0.333333 | E5: =MAX(Global_500_run5!J6,Global_500_run4!J6,Global_500_run3!J6,Global_500_run2!J6,Global_500_run1!J6) -> 0.333333 | H5: =AVERAGE(Global_100_run1!B4,Global_100_run2!B4,Global_100_run3!B4,Global_100_run4!B4,Global_100_run5!B4) -> 0.043104 | I5: =AVERAGE(Global_300_run1!B4,Global_300_run2!B4,Global_300_run3!B4,Global_300_run4!B4,Global_300_run5!B4) -> 0.0423474 | J5: =AVERAGE(Global_500_run1!B4,Global_500_run2!B4,Global_500_run3!B4,Global_500_run4!B4,Global_500_run5!B4) -> 0.0398312 | N5: =AVERAGE(Global_100_run1!E4,Global_100_run2!E4,Global_100_run3!E4,Global_100_run4!E4,Global_100_run5!E4) -> 1 | O5: =AVERAGE(Global_300_run1!E4,Global_300_run2!E4,Global_300_run3!E4,Global_300_run4!E4,Global_300_run5!E4) -> 13 | P5: =AVERAGE(Global_500_run1!E4,Global_500_run2!E4,Global_500_run3!E4,Global_500_run4!E4,Global_500_run5!E4) -> 41
H6: =AVERAGE(Global_100_run1!B5,Global_100_run2!B5,Global_100_run3!B5,Global_100_run4!B5,Global_100_run5!B5) -> 0.0107302 | I6: =AVERAGE(Global_300_run1!B5,Global_300_run2!B5,Global_300_run3!B5,Global_300_run4!B5,Global_300_run5!B5) -> 0.0115748 | J6: =AVERAGE(Global_500_run1!B5,Global_500_run2!B5,Global_500_run3!B5,Global_500_run4!B5,Global_500_run5!B5) -> 0.0102108 | N6: =AVERAGE(Global_100_run1!E5,Global_100_run2!E5,Global_100_run3!E5,Global_100_run4!E5,Global_100_run5!E5) -> 14.8 | O6: =AVERAGE(Global_300_run1!E5,Global_300_run2!E5,Global_300_run3!E5,Global_300_run4!E5,Global_300_run5!E5) -> 79 | P6: =AVERAGE(Global_500_run1!E5,Global_500_run2!E5,Global_500_run3!E5,Global_500_run4!E5,Global_500_run5!E5) -> 154
B7: Min Delta Saturated: | C7: =MIN(Global_100_run5!J9,Global_100_run4!J9,Global_100_run3!J9,Global_100_run2!J9,Global_100_run1!J9) -> 0.097176 | D7: =MIN(Global_300_run5!J9,Global_300_run4!J9,Global_300_run3!J9,Global_300_run2!J9,Global_300_run1!J9) -> 0.333333 | E7: =MIN(Global_500_run5!J6,Global_500_run4!J6,Global_500_run3!J6,Global_500_run2!J6,Global_500_run1!J6) -> 0.333333 | H7: =AVERAGE(Global_100_run1!B6,Global_100_run2!B6,Global_100_run3!B6,Global_100_run4!B6,Global_100_run5!B6) -> 0.0069378 | I7: =AVERAGE(Global_300_run1!B6,Global_300_run2!B6,Global_300_run3!B6,Global_300_run4!B6,Global_300_run5!B6) -> 0.0161008 | J7: =AVERAGE(Global_500_run1!B6,Global_500_run2!B6,Global_500_run3!B6,Global_500_run4!B6,Global_500_run5!B6) -> 0.0072568 | N7: =AVERAGE(Global_100_run1!E6,Global_100_run2!E6,Global_100_run3!E6,Global_100_run4!E6,Global_100_run5!E6) -> 5.6 | O7: =AVERAGE(Global_300_run1!E6,Global_300_run2!E6,Global_300_run3!E6,Global_300_run4!E6,Global_300_run5!E6) -> 24.4 | P7: =AVERAGE(Global_500_run1!E6,Global_500_run2!E6,Global_500_run3!E6,Global_500_run4!E6,Global_500_run5!E6) -> 57.6
H8: =AVERAGE(Global_100_run1!B7,Global_100_run2!B7,Global_100_run3!B7,Global_100_run4!B7,Global_100_run5!B7) -> 0.0093892 | I8: =AVERAGE(Global_300_run1!B7,Global_300_run2!B7,Global_300_run3!B7,Global_300_run4!B7,Global_300_run5!B7) -> 0.0101422 | J8: =AVERAGE(Global_500_run1!B7,Global_500_run2!B7,Global_500_run3!B7,Global_500_run4!B7,Global_500_run5!B7) -> 0.0101976 | N8: =AVERAGE(Global_100_run1!E7,Global_100_run2!E7,Global_100_run3!E7,Global_100_run4!E7,Global_100_run5!E7) -> 4.8 | O8: =AVERAGE(Global_300_run1!E7,Global_300_run2!E7,Global_300_run3!E7,Global_300_run4!E7,Global_300_run5!E7) -> 51.2 | P8: =AVERAGE(Global_500_run1!E7,Global_500_run2!E7,Global_500_run3!E7,Global_500_run4!E7,Global_500_run5!E7) -> 52
B9: Average Saturation Frame: | C9: =AVERAGE(Global_100_run1!N2,Global_100_run2!N2,Global_100_run3!N2,Global_100_run4!N2,Global_100_run5!N2) -> 628.8 | D9: =AVERAGE(Global_300_run1!N2,Global_300_run2!N2,Global_300_run3!N2,Global_300_run4!N2,Global_300_run5!N2) -> 290.8 | E9: =AVERAGE(Global_500_run1!N2,Global_500_run2!N2,Global_500_run3!N2,Global_500_run4!N2,Global_500_run5!N2) -> 200 | F9: More | H9: =AVERAGE(Global_100_run1!B8,Global_100_run2!B8,Global_100_run3!B8,Global_100_run4!B8,Global_100_run5!B8) -> 0.0077438 | I9: =AVERAGE(Global_300_run1!B8,Global_300_run2!B8,Global_300_run3!B8,Global_300_run4!B8,Global_300_run5!B8) -> 0.0076998 | J9: =AVERAGE(Global_500_run1!B8,Global_500_run2!B8,Global_500_run3!B8,Global_500_run4!B8,Global_500_run5!B8) -> 0.0080394 | N9: =AVERAGE(Global_100_run1!E8,Global_100_run2!E8,Global_100_run3!E8,Global_100_run4!E8,Global_100_run5!E8) -> 4.2 | O9: =AVERAGE(Global_300_run1!E8,Global_300_run2!E8,Global_300_run3!E8,Global_300_run4!E8,Global_300_run5!E8) -> 31.4 | P9: =AVERAGE(Global_500_run1!E8,Global_500_run2!E8,Global_500_run3!E8,Global_500_run4!E8,Global_500_run5!E8) -> 47.8
H10: =AVERAGE(Global_100_run1!B9,Global_100_run2!B9,Global_100_run3!B9,Global_100_run4!B9,Global_100_run5!B9) -> 0.0100892 | I10: =AVERAGE(Global_300_run1!B9,Global_300_run2!B9,Global_300_run3!B9,Global_300_run4!B9,Global_300_run5!B9) -> 0.010679 | J10: =AVERAGE(Global_500_run1!B9,Global_500_run2!B9,Global_500_run3!B9,Global_500_run4!B9,Global_500_run5!B9) -> 0.0107692 | N10: =AVERAGE(Global_100_run1!E9,Global_100_run2!E9,Global_100_run3!E9,Global_100_run4!E9,Global_100_run5!E9) -> 3.8 | O10: =AVERAGE(Global_300_run1!E9,Global_300_run2!E9,Global_300_run3!E9,Global_300_run4!E9,Global_300_run5!E9) -> 32.2 | P10: =AVERAGE(Global_500_run1!E9,Global_500_run2!E9,Global_500_run3!E9,Global_500_run4!E9,Global_500_run5!E9) -> 54
B11: Average Ceiling Frame: | C11: 100 | D11: 300 | E11: 500 | H11: =AVERAGE(Global_100_run1!B10,Global_100_run2!B10,Global_100_run3!B10,Global_100_run4!B10,Global_100_run5!B10) -> 0.0076276 | I11: =AVERAGE(Global_300_run1!B10,Global_300_run2!B10,Global_300_run3!B10,Global_300_run4!B10,Global_300_run5!B10) -> 0.0082572 | J11: =AVERAGE(Global_500_run1!B10,Global_500_run2!B10,Global_500_run3!B10,Global_500_run4!B10,Global_500_run5!B10) -> 0.0083016 | N11: =AVERAGE(Global_100_run1!E10,Global_100_run2!E10,Global_100_run3!E10,Global_100_run4!E10,Global_100_run5!E10) -> 4.2 | O11: =AVERAGE(Global_300_run1!E10,Global_300_run2!E10,Global_300_run3!E10,Global_300_run4!E10,Global_300_run5!E10) -> 36.4 | P11: =AVERAGE(Global_500_run1!E10,Global_500_run2!E10,Global_500_run3!E10,Global_500_run4!E10,Global_500_run5!E10) -> 81
C12: None | D12: =AVERAGE(Global_300_run1!N6,Global_300_run2!N6,Global_300_run2!N6,Global_300_run3!N6,Global_300_run4!N6,Global_300_run5!N6) -> 224.83333 | E12: =AVERAGE(Global_500_run1!N6,Global_500_run2!N6,Global_500_run2!N6,Global_500_run3!N6,Global_500_run4!N6,Global_500_run5!N6) -> 128.5 | H12: =AVERAGE(Global_100_run1!B11,Global_100_run2!B11,Global_100_run3!B11,Global_100_run4!B11,Global_100_run5!B11) -> 0.0074674 | I12: =AVERAGE(Global_300_run1!B11,Global_300_run2!B11,Global_300_run3!B11,Global_300_run4!B11,Global_300_run5!B11) -> 0.007741 | J12: =AVERAGE(Global_500_run1!B11,Global_500_run2!B11,Global_500_run3!B11,Global_500_run4!B11,Global_500_run5!B11) -> 0.0076416 | N12: =AVERAGE(Global_100_run1!E11,Global_100_run2!E11,Global_100_run3!E11,Global_100_run4!E11,Global_100_run5!E11) -> 4.6 | O12: =AVERAGE(Global_300_run1!E11,Global_300_run2!E11,Global_300_run3!E11,Global_300_run4!E11,Global_300_run5!E11) -> 34.4 | P12: =AVERAGE(Global_500_run1!E11,Global_500_run2!E11,Global_500_run3!E11,Global_500_run4!E11,Global_500_run5!E11) -> 79.6
H13: =AVERAGE(Global_100_run1!B12,Global_100_run2!B12,Global_100_run3!B12,Global_100_run4!B12,Global_100_run5!B12) -> 0.0075204 | I13: =AVERAGE(Global_300_run1!B12,Global_300_run2!B12,Global_300_run3!B12,Global_300_run4!B12,Global_300_run5!B12) -> 0.007943 | J13: =AVERAGE(Global_500_run1!B12,Global_500_run2!B12,Global_500_run3!B12,Global_500_run4!B12,Global_500_run5!B12) -> 0.008088 | N13: =AVERAGE(Global_100_run1!E12,Global_100_run2!E12,Global_100_run3!E12,Global_100_run4!E12,Global_100_run5!E12) -> 6.4 | O13: =AVERAGE(Global_300_run1!E12,Global_300_run2!E12,Global_300_run3!E12,Global_300_run4!E12,Global_300_run5!E12) -> 35.8 | P13: =AVERAGE(Global_500_run1!E12,Global_500_run2!E12,Global_500_run3!E12,Global_500_run4!E12,Global_500_run5!E12) -> 53.8
H14: =AVERAGE(Global_100_run1!B13,Global_100_run2!B13,Global_100_run3!B13,Global_100_run4!B13,Global_100_run5!B13) -> 0.0074594 | I14: =AVERAGE(Global_300_run1!B13,Global_300_run2!B13,Global_300_run3!B13,Global_300_run4!B13,Global_300_run5!B13) -> 0.0080994 | J14: =AVERAGE(Global_500_run1!B13,Global_500_run2!B13,Global_500_run3!B13,Global_500_run4!B13,Global_500_run5!B13) -> 0.0079604 | N14: =AVERAGE(Global_100_run1!E13,Global_100_run2!E13,Global_100_run3!E13,Global_100_run4!E13,Global_100_run5!E13) -> 4.8 | O14: =AVERAGE(Global_300_run1!E13,Global_300_run2!E13,Global_300_run3!E13,Global_300_run4!E13,Global_300_run5!E13) -> 35.6 | P14: =AVERAGE(Global_500_run1!E13,Global_500_run2!E13,Global_500_run3!E13,Global_500_run4!E13,Global_500_run5!E13) -> 67.4
H15: =AVERAGE(Global_100_run1!B14,Global_100_run2!B14,Global_100_run3!B14,Global_100_run4!B14,Global_100_run5!B14) -> 0.0089546 | I15: =AVERAGE(Global_300_run1!B14,Global_300_run2!B14,Global_300_run3!B14,Global_300_run4!B14,Global_300_run5!B14) -> 0.0081196 | J15: =AVERAGE(Global_500_run1!B14,Global_500_run2!B14,Global_500_run3!B14,Global_500_run4!B14,Global_500_run5!B14) -> 0.0081452 | N15: =AVERAGE(Global_100_run1!E14,Global_100_run2!E14,Global_100_run3!E14,Global_100_run4!E14,Global_100_run5!E14) -> 4.4 | O15: =AVERAGE(Global_300_run1!E14,Global_300_run2!E14,Global_300_run3!E14,Global_300_run4!E14,Global_300_run5!E14) -> 35 | P15: =AVERAGE(Global_500_run1!E14,Global_500_run2!E14,Global_500_run3!E14,Global_500_run4!E14,Global_500_run5!E14) -> 61.2
H16: =AVERAGE(Global_100_run1!B15,Global_100_run2!B15,Global_100_run3!B15,Global_100_run4!B15,Global_100_run5!B15) -> 0.007449 | I16: =AVERAGE(Global_300_run1!B15,Global_300_run2!B15,Global_300_run3!B15,Global_300_run4!B15,Global_300_run5!B15) -> 0.0075904 | J16: =AVERAGE(Global_500_run1!B15,Global_500_run2!B15,Global_500_run3!B15,Global_500_run4!B15,Global_500_run5!B15) -> 0.007565 | N16: =AVERAGE(Global_100_run1!E15,Global_100_run2!E15,Global_100_run3!E15,Global_100_run4!E15,Global_100_run5!E15) -> 7.8 | O16: =AVERAGE(Global_300_run1!E15,Global_300_run2!E15,Global_300_run3!E15,Global_300_run4!E15,Global_300_run5!E15) -> 31.6 | P16: =AVERAGE(Global_500_run1!E15,Global_500_run2!E15,Global_500_run3!E15,Global_500_run4!E15,Global_500_run5!E15) -> 87.2
H17: =AVERAGE(Global_100_run1!B16,Global_100_run2!B16,Global_100_run3!B16,Global_100_run4!B16,Global_100_run5!B16) -> 0.0082814 | I17: =AVERAGE(Global_300_run1!B16,Global_300_run2!B16,Global_300_run3!B16,Global_300_run4!B16,Global_300_run5!B16) -> 0.0087218 | J17: =AVERAGE(Global_500_run1!B16,Global_500_run2!B16,Global_500_run3!B16,Global_500_run4!B16,Global_500_run5!B16) -> 0.0083386 | N17: =AVERAGE(Global_100_run1!E16,Global_100_run2!E16,Global_100_run3!E16,Global_100_run4!E16,Global_100_run5!E16) -> 8 | O17: =AVERAGE(Global_300_run1!E16,Global_300_run2!E16,Global_300_run3!E16,Global_300_run4!E16,Global_300_run5!E16) -> 42 | P17: =AVERAGE(Global_500_run1!E16,Global_500_run2!E16,Global_500_run3!E16,Global_500_run4!E16,Global_500_run5!E16) -> 90.2
H18: =AVERAGE(Global_100_run1!B17,Global_100_run2!B17,Global_100_run3!B17,Global_100_run4!B17,Global_100_run5!B17) -> 0.0083016 | I18: =AVERAGE(Global_300_run1!B17,Global_300_run2!B17,Global_300_run3!B17,Global_300_run4!B17,Global_300_run5!B17) -> 0.0086752 | J18: =AVERAGE(Global_500_run1!B17,Global_500_run2!B17,Global_500_run3!B17,Global_500_run4!B17,Global_500_run5!B17) -> 0.0090732 | N18: =AVERAGE(Global_100_run1!E17,Global_100_run2!E17,Global_100_run3!E17,Global_100_run4!E17,Global_100_run5!E17) -> 8 | O18: =AVERAGE(Global_300_run1!E17,Global_300_run2!E17,Global_300_run3!E17,Global_300_run4!E17,Global_300_run5!E17) -> 54.4 | P18: =AVERAGE(Global_500_run1!E17,Global_500_run2!E17,Global_500_run3!E17,Global_500_run4!E17,Global_500_run5!E17) -> 72
H19: =AVERAGE(Global_100_run1!B18,Global_100_run2!B18,Global_100_run3!B18,Global_100_run4!B18,Global_100_run5!B18) -> 0.008215 | I19: =AVERAGE(Global_300_run1!B18,Global_300_run2!B18,Global_300_run3!B18,Global_300_run4!B18,Global_300_run5!B18) -> 0.008391 | J19: =AVERAGE(Global_500_run1!B18,Global_500_run2!B18,Global_500_run3!B18,Global_500_run4!B18,Global_500_run5!B18) -> 0.0091922 | N19: =AVERAGE(Global_100_run1!E18,Global_100_run2!E18,Global_100_run3!E18,Global_100_run4!E18,Global_100_run5!E18) -> 8.8 | O19: =AVERAGE(Global_300_run1!E18,Global_300_run2!E18,Global_300_run3!E18,Global_300_run4!E18,Global_300_run5!E18) -> 48.8 | P19: =AVERAGE(Global_500_run1!E18,Global_500_run2!E18,Global_500_run3!E18,Global_500_run4!E18,Global_500_run5!E18) -> 91.2
H20: =AVERAGE(Global_100_run1!B19,Global_100_run2!B19,Global_100_run3!B19,Global_100_run4!B19,Global_100_run5!B19) -> 0.0086112 | I20: =AVERAGE(Global_300_run1!B19,Global_300_run2!B19,Global_300_run3!B19,Global_300_run4!B19,Global_300_run5!B19) -> 0.007851 | J20: =AVERAGE(Global_500_run1!B19,Global_500_run2!B19,Global_500_run3!B19,Global_500_run4!B19,Global_500_run5!B19) -> 0.0076424 | N20: =AVERAGE(Global_100_run1!E19,Global_100_run2!E19,Global_100_run3!E19,Global_100_run4!E19,Global_100_run5!E19) -> 8.8 | O20: =AVERAGE(Global_300_run1!E19,Global_300_run2!E19,Global_300_run3!E19,Global_300_run4!E19,Global_300_run5!E19) -> 48.8 | P20: =AVERAGE(Global_500_run1!E19,Global_500_run2!E19,Global_500_run3!E19,Global_500_run4!E19,Global_500_run5!E19) -> 111.6
H21: =AVERAGE(Global_100_run1!B20,Global_100_run2!B20,Global_100_run3!B20,Global_100_run4!B20,Global_100_run5!B20) -> 0.0072786 | I21: =AVERAGE(Global_300_run1!B20,Global_300_run2!B20,Global_300_run3!B20,Global_300_run4!B20,Global_300_run5!B20) -> 0.0077552 | J21: =AVERAGE(Global_500_run1!B20,Global_500_run2!B20,Global_500_run3!B20,Global_500_run4!B20,Global_500_run5!B20) -> 0.0078016 | N21: =AVERAGE(Global_100_run1!E20,Global_100_run2!E20,Global_100_run3!E20,Global_100_run4!E20,Global_100_run5!E20) -> 8.6 | O21: =AVERAGE(Global_300_run1!E20,Global_300_run2!E20,Global_300_run3!E20,Global_300_run4!E20,Global_300_run5!E20) -> 53.6 | P21: =AVERAGE(Global_500_run1!E20,Global_500_run2!E20,Global_500_run3!E20,Global_500_run4!E20,Global_500_run5!E20) -> 107.8
H22: =AVERAGE(Global_100_run1!B21,Global_100_run2!B21,Global_100_run3!B21,Global_100_run4!B21,Global_100_run5!B21) -> 0.0070482 | I22: =AVERAGE(Global_300_run1!B21,Global_300_run2!B21,Global_300_run3!B21,Global_300_run4!B21,Global_300_run5!B21) -> 0.0078156 | J22: =AVERAGE(Global_500_run1!B21,Global_500_run2!B21,Global_500_run3!B21,Global_500_run4!B21,Global_500_run5!B21) -> 0.0073234 | N22: =AVERAGE(Global_100_run1!E21,Global_100_run2!E21,Global_100_run3!E21,Global_100_run4!E21,Global_100_run5!E21) -> 6.4 | O22: =AVERAGE(Global_300_run1!E21,Global_300_run2!E21,Global_300_run3!E21,Global_300_run4!E21,Global_300_run5!E21) -> 29.8 | P22: =AVERAGE(Global_500_run1!E21,Global_500_run2!E21,Global_500_run3!E21,Global_500_run4!E21,Global_500_run5!E21) -> 107
H23: =AVERAGE(Global_100_run1!B22,Global_100_run2!B22,Global_100_run3!B22,Global_100_run4!B22,Global_100_run5!B22) -> 0.0072086 | I23: =AVERAGE(Global_300_run1!B22,Global_300_run2!B22,Global_300_run3!B22,Global_300_run4!B22,Global_300_run5!B22) -> 0.0072048 | J23: =AVERAGE(Global_500_run1!B22,Global_500_run2!B22,Global_500_run3!B22,Global_500_run4!B22,Global_500_run5!B22) -> 0.0077418 | N23: =AVERAGE(Global_100_run1!E22,Global_100_run2!E22,Global_100_run3!E22,Global_100_run4!E22,Global_100_run5!E22) -> 7.2 | O23: =AVERAGE(Global_300_run1!E22,Global_300_run2!E22,Global_300_run3!E22,Global_300_run4!E22,Global_300_run5!E22) -> 49.2 | P23: =AVERAGE(Global_500_run1!E22,Global_500_run2!E22,Global_500_run3!E22,Global_500_run4!E22,Global_500_run5!E22) -> 88.2
H24: =AVERAGE(Global_100_run1!B23,Global_100_run2!B23,Global_100_run3!B23,Global_100_run4!B23,Global_100_run5!B23) -> 0.0070374 | I24: =AVERAGE(Global_300_run1!B23,Global_300_run2!B23,Global_300_run3!B23,Global_300_run4!B23,Global_300_run5!B23) -> 0.0074208 | J24: =AVERAGE(Global_500_run1!B23,Global_500_run2!B23,Global_500_run3!B23,Global_500_run4!B23,Global_500_run5!B23) -> 0.0072706 | N24: =AVERAGE(Global_100_run1!E23,Global_100_run2!E23,Global_100_run3!E23,Global_100_run4!E23,Global_100_run5!E23) -> 9 | O24: =AVERAGE(Global_300_run1!E23,Global_300_run2!E23,Global_300_run3!E23,Global_300_run4!E23,Global_300_run5!E23) -> 50.6 | P24: =AVERAGE(Global_500_run1!E23,Global_500_run2!E23,Global_500_run3!E23,Global_500_run4!E23,Global_500_run5!E23) -> 114.8
... H202: =AVERAGE(Global_100_run1!B201,Global_100_run2!B201,Global_100_run3!B201,Global_100_run4!B201,Global_100_run5!B201) -> 0.0060684 | I202: =AVERAGE(Global_300_run1!B201,Global_300_run2!B201,Global_300_run3!B201,Global_300_run4!B201,Global_300_run5!B201) -> 0.1264384 | J202: =AVERAGE(Global_500_run1!B201,Global_500_run2!B201,Global_500_run3!B201,Global_500_run4!B201,Global_500_run5!B201) -> 0.333333 | N202: =AVERAGE(Global_100_run1!E201,Global_100_run2!E201,Global_100_run3!E201,Global_100_run4!E201,Global_100_run5!E201) -> 69.8 | O202: =AVERAGE(Global_300_run1!E201,Global_300_run2!E201,Global_300_run3!E201,Global_300_run4!E201,Global_300_run5!E201) -> 3678 | P202: =AVERAGE(Global_500_run1!E201,Global_500_run2!E201,Global_500_run3!E201,Global_500_run4!E201,Global_500_run5!E201) -> 24136.6
H203: =AVERAGE(Global_100_run1!B202,Global_100_run2!B202,Global_100_run3!B202,Global_100_run4!B202,Global_100_run5!B202) -> 0.006104 | I203: =AVERAGE(Global_300_run1!B202,Global_300_run2!B202,Global_300_run3!B202,Global_300_run4!B202,Global_300_run5!B202) -> 0.1326756 | N203: =AVERAGE(Global_100_run1!E202,Global_100_run2!E202,Global_100_run3!E202,Global_100_run4!E202,Global_100_run5!E202) -> 90.6 | O203: =AVERAGE(Global_300_run1!E202,Global_300_run2!E202,Global_300_run3!E202,Global_300_run4!E202,Global_300_run5!E202) -> 3684
H204: =AVERAGE(Global_100_run1!B203,Global_100_run2!B203,Global_100_run3!B203,Global_100_run4!B203,Global_100_run5!B203) -> 0.006057 | I204: =AVERAGE(Global_300_run1!B203,Global_300_run2!B203,Global_300_run3!B203,Global_300_run4!B203,Global_300_run5!B203) -> 0.1400662 | N204: =AVERAGE(Global_100_run1!E203,Global_100_run2!E203,Global_100_run3!E203,Global_100_run4!E203,Global_100_run5!E203) -> 69 | O204: =AVERAGE(Global_300_run1!E203,Global_300_run2!E203,Global_300_run3!E203,Global_300_run4!E203,Global_300_run5!E203) -> 3780.4
H205: =AVERAGE(Global_100_run1!B204,Global_100_run2!B204,Global_100_run3!B204,Global_100_run4!B204,Global_100_run5!B204) -> 0.0061108 | I205: =AVERAGE(Global_300_run1!B204,Global_300_run2!B204,Global_300_run3!B204,Global_300_run4!B204,Global_300_run5!B204) -> 0.148001 | N205: =AVERAGE(Global_100_run1!E204,Global_100_run2!E204,Global_100_run3!E204,Global_100_run4!E204,Global_100_run5!E204) -> 91 | O205: =AVERAGE(Global_300_run1!E204,Global_300_run2!E204,Global_300_run3!E204,Global_300_run4!E204,Global_300_run5!E204) -> 3822.4
H206: =AVERAGE(Global_100_run1!B205,Global_100_run2!B205,Global_100_run3!B205,Global_100_run4!B205,Global_100_run5!B205) -> 0.0060514 | I206: =AVERAGE(Global_300_run1!B205,Global_300_run2!B205,Global_300_run3!B205,Global_300_run4!B205,Global_300_run5!B205) -> 0.1539534 | N206: =AVERAGE(Global_100_run1!E205,Global_100_run2!E205,Global_100_run3!E205,Global_100_run4!E205,Global_100_run5!E205) -> 69 | O206: =AVERAGE(Global_300_run1!E205,Global_300_run2!E205,Global_300_run3!E205,Global_300_run4!E205,Global_300_run5!E205) -> 3947.2
H207: =AVERAGE(Global_100_run1!B206,Global_100_run2!B206,Global_100_run3!B206,Global_100_run4!B206,Global_100_run5!B206) -> 0.0060554 | I207: =AVERAGE(Global_300_run1!B206,Global_300_run2!B206,Global_300_run3!B206,Global_300_run4!B206,Global_300_run5!B206) -> 0.1610256 | N207: =AVERAGE(Global_100_run1!E206,Global_100_run2!E206,Global_100_run3!E206,Global_100_run4!E206,Global_100_run5!E206) -> 95.8 | O207: =AVERAGE(Global_300_run1!E206,Global_300_run2!E206,Global_300_run3!E206,Global_300_run4!E206,Global_300_run5!E206) -> 4225.6
H208: =AVERAGE(Global_100_run1!B207,Global_100_run2!B207,Global_100_run3!B207,Global_100_run4!B207,Global_100_run5!B207) -> 0.0060766 | I208: =AVERAGE(Global_300_run1!B207,Global_300_run2!B207,Global_300_run3!B207,Global_300_run4!B207,Global_300_run5!B207) -> 0.169547 | N208: =AVERAGE(Global_100_run1!E207,Global_100_run2!E207,Global_100_run3!E207,Global_100_run4!E207,Global_100_run5!E207) -> 95.2 | O208: =AVERAGE(Global_300_run1!E207,Global_300_run2!E207,Global_300_run3!E207,Global_300_run4!E207,Global_300_run5!E207) -> 4270.4
H209: =AVERAGE(Global_100_run1!B208,Global_100_run2!B208,Global_100_run3!B208,Global_100_run4!B208,Global_100_run5!B208) -> 0.0060822 | I209: =AVERAGE(Global_300_run1!B208,Global_300_run2!B208,Global_300_run3!B208,Global_300_run4!B208,Global_300_run5!B208) -> 0.1763602 | N209: =AVERAGE(Global_100_run1!E208,Global_100_run2!E208,Global_100_run3!E208,Global_100_run4!E208,Global_100_run5!E208) -> 95.8 | O209: =AVERAGE(Global_300_run1!E208,Global_300_run2!E208,Global_300_run3!E208,Global_300_run4!E208,Global_300_run5!E208) -> 4465
H210: =AVERAGE(Global_100_run1!B209,Global_100_run2!B209,Global_100_run3!B209,Global_100_run4!B209,Global_100_run5!B209) -> 0.0060686 | I210: =AVERAGE(Global_300_run1!B209,Global_300_run2!B209,Global_300_run3!B209,Global_300_run4!B209,Global_300_run5!B209) -> 0.1857418 | N210: =AVERAGE(Global_100_run1!E209,Global_100_run2!E209,Global_100_run3!E209,Global_100_run4!E209,Global_100_run5!E209) -> 71.6 | O210: =AVERAGE(Global_300_run1!E209,Global_300_run2!E209,Global_300_run3!E209,Global_300_run4!E209,Global_300_run5!E209) -> 4741.2
H211: =AVERAGE(Global_100_run1!B210,Global_100_run2!B210,Global_100_run3!B210,Global_100_run4!B210,Global_100_run5!B210) -> 0.00608 | I211: =AVERAGE(Global_300_run1!B210,Global_300_run2!B210,Global_300_run3!B210,Global_300_run4!B210,Global_300_run5!B210) -> 0.1925452 | N211: =AVERAGE(Global_100_run1!E210,Global_100_run2!E210,Global_100_run3!E210,Global_100_run4!E210,Global_100_run5!E210) -> 97.6 | O211: =AVERAGE(Global_300_run1!E210,Global_300_run2!E210,Global_300_run3!E210,Global_300_run4!E210,Global_300_run5!E210) -> 4701.2
H212: =AVERAGE(Global_100_run1!B211,Global_100_run2!B211,Global_100_run3!B211,Global_100_run4!B211,Global_100_run5!B211) -> 0.0061718 | I212: =AVERAGE(Global_300_run1!B211,Global_300_run2!B211,Global_300_run3!B211,Global_300_run4!B211,Global_300_run5!B211) -> 0.2039992 | N212: =AVERAGE(Global_100_run1!E211,Global_100_run2!E211,Global_100_run3!E211,Global_100_run4!E211,Global_100_run5!E211) -> 100.4 | O212: =AVERAGE(Global_300_run1!E211,Global_300_run2!E211,Global_300_run3!E211,Global_300_run4!E211,Global_300_run5!E211) -> 4969.4
H213: =AVERAGE(Global_100_run1!B212,Global_100_run2!B212,Global_100_run3!B212,Global_100_run4!B212,Global_100_run5!B212) -> 0.0060434 | I213: =AVERAGE(Global_300_run1!B212,Global_300_run2!B212,Global_300_run3!B212,Global_300_run4!B212,Global_300_run5!B212) -> 0.2089706 | N213: =AVERAGE(Global_100_run1!E212,Global_100_run2!E212,Global_100_run3!E212,Global_100_run4!E212,Global_100_run5!E212) -> 73.8 | O213: =AVERAGE(Global_300_run1!E212,Global_300_run2!E212,Global_300_run3!E212,Global_300_run4!E212,Global_300_run5!E212) -> 5221.6
H214: =AVERAGE(Global_100_run1!B213,Global_100_run2!B213,Global_100_run3!B213,Global_100_run4!B213,Global_100_run5!B213) -> 0.0062198 | I214: =AVERAGE(Global_300_run1!B213,Global_300_run2!B213,Global_300_run3!B213,Global_300_run4!B213,Global_300_run5!B213) -> 0.218015 | N214: =AVERAGE(Global_100_run1!E213,Global_100_run2!E213,Global_100_run3!E213,Global_100_run4!E213,Global_100_run5!E213) -> 101.2 | O214: =AVERAGE(Global_300_run1!E213,Global_300_run2!E213,Global_300_run3!E213,Global_300_run4!E213,Global_300_run5!E213) -> 5134.4
... H402: =AVERAGE(Global_100_run1!B401,Global_100_run2!B401,Global_100_run3!B401,Global_100_run4!B401,Global_100_run5!B401) -> 0.0062398 | I402: =AVERAGE(Global_300_run1!B401,Global_300_run2!B401,Global_300_run3!B401,Global_300_run4!B401,Global_300_run5!B401) -> 0.333333 | N402: =AVERAGE(Global_100_run1!E401,Global_100_run2!E401,Global_100_run3!E401,Global_100_run4!E401,Global_100_run5!E401) -> 178.2 | O402: =AVERAGE(Global_300_run1!E401,Global_300_run2!E401,Global_300_run3!E401,Global_300_run4!E401,Global_300_run5!E401) -> 11163.6
H403: =AVERAGE(Global_100_run1!B402,Global_100_run2!B402,Global_100_run3!B402,Global_100_run4!B402,Global_100_run5!B402) -> 0.0057036 | N403: =AVERAGE(Global_100_run1!E402,Global_100_run2!E402,Global_100_run3!E402,Global_100_run4!E402,Global_100_run5!E402) -> 134.8
H404: =AVERAGE(Global_100_run1!B403,Global_100_run2!B403,Global_100_run3!B403,Global_100_run4!B403,Global_100_run5!B403) -> 0.0057174 | N404: =AVERAGE(Global_100_run1!E403,Global_100_run2!E403,Global_100_run3!E403,Global_100_run4!E403,Global_100_run5!E403) -> 139
