Workbook

Sheet UniformGrid_500_run5
A1: Frame | B1: DeltaTime | C1: ParticleCount | D1: ChannelCollisions | E1: SphereCollisions
A2: 1 | B2: 0.02 | C2: 0 | D2: 0 | E2: 0 | I2: Average Delta Total: | J2: =AVERAGE(B:B) -> 0.12558856 | M2: Frame Saturation: | N2: 323
A3: 2 | B3: 0.02 | C3: 8 | D3: 48 | E3: 5 | I3: Average Delta Saturated: | J3: =AVERAGE(B324:B801) -> 0.17781507
A4: 3 | B4: 0.037223 | C4: 16 | D4: 112 | E4: 52 | M4: Total Frames: | N4: 800
A5: 4 | B5: 0.016766 | C5: 37 | D5: 572 | E5: 132 | I5: Max Delta Total | J5: =MAX(B:B) -> 0.194803
A6: 5 | B6: 0.008147 | C6: 45 | D6: 344 | E6: 87 | I6: Max Delta Saturated: | J6: =MAX(B324:B801) -> 0.194803
A7: 6 | B7: 0.008787 | C7: 49 | D7: 196 | E7: 61
A8: 7 | B8: 0.008792 | C8: 54 | D8: 216 | E8: 60 | I8: Min Delta Total | J8: =MIN(B:B) -> 0.004133
A9: 8 | B9: 0.00923 | C9: 58 | D9: 232 | E9: 66 | I9: Min Delta Saturated | J9: =MIN(B324:B801) -> 0.173264
A10: 9 | B10: 0.008758 | C10: 62 | D10: 248 | E10: 67
A11: 10 | B11: 0.00799 | C11: 66 | D11: 264 | E11: 67 | I11: Average Particle Count Saturated: | J11: =AVERAGE(C324:C801) -> 3088.9059
A12: 11 | B12: 0.008379 | C12: 70 | D12: 280 | E12: 80
A13: 12 | B13: 0.008044 | C13: 74 | D13: 296 | E13: 80 | I13: Channel Collisions Saturated: | J13: =AVERAGE(D324:D801) -> 98980.569
A14: 13 | B14: 0.008976 | C14: 79 | D14: 316 | E14: 83
A15: 14 | B15: 0.008048 | C15: 83 | D15: 332 | E15: 95 | I15: Sphere Collisions Saturated: | J15: =AVERAGE(E324:E801) -> 22927.174
A16: 15 | B16: 0.008631 | C16: 87 | D16: 348 | E16: 104
A17: 16 | B17: 0.008407 | C17: 91 | D17: 364 | E17: 95
A18: 17 | B18: 0.009028 | C18: 95 | D18: 380 | E18: 96
A19: 18 | B19: 0.0068 | C19: 99 | D19: 396 | E19: 109
A20: 19 | B20: 0.007605 | C20: 104 | D20: 416 | E20: 96
A21: 20 | B21: 0.00703 | C21: 108 | D21: 432 | E21: 109
A22: 21 | B22: 0.007656 | C22: 112 | D22: 448 | E22: 135
A23: 22 | B23: 0.007002 | C23: 116 | D23: 464 | E23: 131
A24: 23 | B24: 0.006981 | C24: 116 | D24: 0 | E24: 0
A25: 24 | B25: 0.007621 | C25: 120 | D25: 480 | E25: 129
A26: 25 | B26: 0.006988 | C26: 124 | D26: 496 | E26: 126
A27: 26 | B27: 0.007629 | C27: 129 | D27: 516 | E27: 155
... A801: 800 | B801: 0.177926 | C801: 3090 | D801: 99056 | E801: 23112

Sheet UniformGrid_500_run4
A1: Frame | B1: DeltaTime | C1: ParticleCount | D1: ChannelCollisions | E1: SphereCollisions
A2: 1 | B2: 0.02 | C2: 0 | D2: 0 | E2: 0 | I2: Average Delta Total: | J2: =AVERAGE(B:B) -> 0.12319311 | M2: Frame Saturation: | N2: 323
A3: 2 | B3: 0.02 | C3: 8 | D3: 48 | E3: 5 | I3: Average Delta Saturated: | J3: =AVERAGE(B324:B801) -> 0.17447781
A4: 3 | B4: 0.036071 | C4: 16 | D4: 112 | E4: 52 | M4: Total Frames: | N4: 800
A5: 4 | B5: 0.01084 | C5: 37 | D5: 572 | E5: 132 | I5: Max Delta Total | J5: =MAX(B:B) -> 0.189231
A6: 5 | B6: 0.008415 | C6: 41 | D6: 164 | E6: 38 | I6: Max Delta Saturated: | J6: =MAX(B324:B801) -> 0.189231
A7: 6 | B7: 0.011746 | C7: 45 | D7: 180 | E7: 49
A8: 7 | B8: 0.007964 | C8: 49 | D8: 196 | E8: 61 | I8: Min Delta Total | J8: =MIN(B:B) -> 0.004153
A9: 8 | B9: 0.012092 | C9: 54 | D9: 216 | E9: 60 | I9: Min Delta Saturated | J9: =MIN(B324:B801) -> 0.171606
A10: 9 | B10: 0.008797 | C10: 62 | D10: 480 | E10: 133
A11: 10 | B11: 0.008179 | C11: 66 | D11: 264 | E11: 67 | I11: Average Particle Count Saturated: | J11: =AVERAGE(C324:C801) -> 3088.8619
A12: 11 | B12: 0.009009 | C12: 70 | D12: 280 | E12: 80
A13: 12 | B13: 0.008293 | C13: 74 | D13: 296 | E13: 80 | I13: Channel Collisions Saturated: | J13: =AVERAGE(D324:D801) -> 98980.385
A14: 13 | B14: 0.008979 | C14: 79 | D14: 316 | E14: 83
A15: 14 | B15: 0.007936 | C15: 83 | D15: 332 | E15: 95 | I15: Sphere Collisions Saturated: | J15: =AVERAGE(E324:E801) -> 22926.994
A16: 15 | B16: 0.008611 | C16: 87 | D16: 348 | E16: 104
A17: 16 | B17: 0.009401 | C17: 91 | D17: 364 | E17: 95
A18: 17 | B18: 0.00962 | C18: 95 | D18: 380 | E18: 96
A19: 18 | B19: 0.008087 | C19: 99 | D19: 396 | E19: 109
A20: 19 | B20: 0.008822 | C20: 104 | D20: 416 | E20: 96
A21: 20 | B21: 0.008334 | C21: 108 | D21: 432 | E21: 109
A22: 21 | B22: 0.008643 | C22: 112 | D22: 448 | E22: 135
A23: 22 | B23: 0.008165 | C23: 116 | D23: 464 | E23: 131
A24: 23 | B24: 0.008634 | C24: 120 | D24: 480 | E24: 129
A25: 24 | B25: 0.008074 | C25: 124 | D25: 496 | E25: 126
A26: 25 | B26: 0.008773 | C26: 129 | D26: 516 | E26: 155
A27: 26 | B27: 0.008218 | C27: 133 | D27: 532 | E27: 166
... A801: 800 | B801: 0.174322 | C801: 3092 | D801: 99052 | E801: 22825

Sheet UniformGrid_500_run3
A1: Frame | B1: DeltaTime | C1: ParticleCount | D1: ChannelCollisions | E1: SphereCollisions
A2: 1 | B2: 0.02 | C2: 0 | D2: 0 | E2: 0 | I2: Average Delta Total: | J2: =AVERAGE(B:B) -> 0.12345781 | M2: Frame Saturation: | N2: 325
A3: 2 | B3: 0.02 | C3: 8 | D3: 48 | E3: 5 | I3: Average Delta Saturated: | J3: =AVERAGE(B326:B801) -> 0.17538949
A4: 3 | B4: 0.047629 | C4: 16 | D4: 112 | E4: 52 | M4: Total Frames: | N4: 800
A5: 4 | B5: 0.009835 | C5: 41 | D5: 736 | E5: 170 | I5: Max Delta Total | J5: =MAX(B:B) -> 0.207765
A6: 5 | B6: 0.008075 | C6: 45 | D6: 180 | E6: 49 | I6: Max Delta Saturated: | J6: =MAX(B326:B801) -> 0.207765
A7: 6 | B7: 0.012007 | C7: 49 | D7: 196 | E7: 61
A8: 7 | B8: 0.00923 | C8: 58 | D8: 448 | E8: 126 | I8: Min Delta Total | J8: =MIN(B:B) -> 0.004062
A9: 8 | B9: 0.008384 | C9: 62 | D9: 248 | E9: 67 | I9: Min Delta Saturated | J9: =MIN(B326:B801) -> 0.1726
A10: 9 | B10: 0.00879 | C10: 66 | D10: 264 | E10: 67
A11: 10 | B11: 0.008147 | C11: 70 | D11: 280 | E11: 80 | I11: Average Particle Count Saturated: | J11: =AVERAGE(C326:C801) -> 3088.8529
A12: 11 | B12: 0.00883 | C12: 74 | D12: 296 | E12: 80
A13: 12 | B13: 0.008242 | C13: 79 | D13: 316 | E13: 83 | I13: Channel Collisions Saturated: | J13: =AVERAGE(D326:D801) -> 98980.16
A14: 13 | B14: 0.008796 | C14: 83 | D14: 332 | E14: 95
A15: 14 | B15: 0.008228 | C15: 87 | D15: 348 | E15: 104 | I15: Sphere Collisions Saturated: | J15: =AVERAGE(E326:E801) -> 22927.54
A16: 15 | B16: 0.010282 | C16: 91 | D16: 364 | E16: 95
A17: 16 | B17: 0.010545 | C17: 95 | D17: 380 | E17: 96
A18: 17 | B18: 0.00793 | C18: 99 | D18: 396 | E18: 109
A19: 18 | B19: 0.007462 | C19: 104 | D19: 416 | E19: 96
A20: 19 | B20: 0.006694 | C20: 108 | D20: 432 | E20: 109
A21: 20 | B21: 0.00675 | C21: 112 | D21: 448 | E21: 135
A22: 21 | B22: 0.007298 | C22: 116 | D22: 464 | E22: 131
A23: 22 | B23: 0.0068 | C23: 120 | D23: 480 | E23: 129
A24: 23 | B24: 0.007473 | C24: 120 | D24: 0 | E24: 0
A25: 24 | B25: 0.006435 | C25: 124 | D25: 496 | E25: 126
A26: 25 | B26: 0.006874 | C26: 129 | D26: 516 | E26: 155
A27: 26 | B27: 0.007166 | C27: 133 | D27: 532 | E27: 166
... A801: 800 | B801: 0.175943 | C801: 3090 | D801: 99048 | E801: 22823

Sheet UniformGrid_500_run2
A1: Frame | B1: DeltaTime | C1: ParticleCount | D1: ChannelCollisions | E1: SphereCollisions
A2: 1 | B2: 0.02 | C2: 0 | D2: 0 | E2: 0 | I2: Average Delta Total: | J2: =AVERAGE(B:B) -> 0.12193607 | M2: Frame Saturation: | N2: 331
A3: 2 | B3: 0.02 | C3: 8 | D3: 48 | E3: 5 | I3: Average Delta Saturated: | J3: =AVERAGE(B332:B801) -> 0.175658
A4: 3 | B4: 0.036312 | C4: 16 | D4: 112 | E4: 52 | M4: Total Frames: | N4: 800
A5: 4 | B5: 0.010725 | C5: 37 | D5: 572 | E5: 132 | I5: Max Delta Total | J5: =MAX(B:B) -> 0.216296
A6: 5 | B6: 0.007702 | C6: 41 | D6: 164 | E6: 38 | I6: Max Delta Saturated: | J6: =MAX(B332:B801) -> 0.216296
A7: 6 | B7: 0.010768 | C7: 45 | D7: 180 | E7: 49
A8: 7 | B8: 0.007962 | C8: 49 | D8: 196 | E8: 61 | I8: Min Delta Total | J8: =MIN(B:B) -> 0.004184
A9: 8 | B9: 0.011794 | C9: 54 | D9: 216 | E9: 60 | I9: Min Delta Saturated | J9: =MIN(B332:B801) -> 0.171653
A10: 9 | B10: 0.008045 | C10: 62 | D10: 480 | E10: 133
A11: 10 | B11: 0.008921 | C11: 62 | D11: 0 | E11: 0 | I11: Average Particle Count Saturated: | J11: =AVERAGE(C332:C801) -> 3089.0702
A12: 11 | B12: 0.008115 | C12: 70 | D12: 544 | E12: 147
A13: 12 | B13: 0.009011 | C13: 74 | D13: 296 | E13: 80 | I13: Channel Collisions Saturated: | J13: =AVERAGE(D332:D801) -> 98979.634
A14: 13 | B14: 0.008138 | C14: 79 | D14: 316 | E14: 83
A15: 14 | B15: 0.008836 | C15: 83 | D15: 332 | E15: 95 | I15: Sphere Collisions Saturated: | J15: =AVERAGE(E332:E801) -> 22927.298
A16: 15 | B16: 0.008079 | C16: 87 | D16: 348 | E16: 104
A17: 16 | B17: 0.010737 | C17: 91 | D17: 364 | E17: 95
A18: 17 | B18: 0.010682 | C18: 95 | D18: 380 | E18: 96
A19: 18 | B19: 0.008142 | C19: 99 | D19: 396 | E19: 109
A20: 19 | B20: 0.008567 | C20: 104 | D20: 416 | E20: 96
A21: 20 | B21: 0.008258 | C21: 108 | D21: 432 | E21: 109
A22: 21 | B22: 0.008771 | C22: 112 | D22: 448 | E22: 135
A23: 22 | B23: 0.008136 | C23: 116 | D23: 464 | E23: 131
A24: 23 | B24: 0.006167 | C24: 120 | D24: 480 | E24: 129
A25: 24 | B25: 0.005962 | C25: 124 | D25: 496 | E25: 126
A26: 25 | B26: 0.005525 | C26: 129 | D26: 516 | E26: 155
A27: 26 | B27: 0.00488 | C27: 129 | D27: 0 | E27: 0
... A801: 800 | B801: 0.181637 | C801: 3091 | D801: 98984 | E801: 23270

Sheet UniformGrid_500_run1
A1: Frame | B1: DeltaTime | C1: ParticleCount | D1: ChannelCollisions | E1: SphereCollisions
A2: 1 | B2: 0.02 | C2: 0 | D2: 0 | E2: 0 | I2: Average Delta Total: | J2: =AVERAGE(B:B) -> 0.1485246 | M2: Frame Saturation: | N2: 276
A3: 2 | B3: 0.02 | C3: 8 | D3: 48 | E3: 5 | I3: Average Delta Saturated: | J3: =AVERAGE(B277:B801) -> 0.19587085
A4: 3 | B4: 0.046702 | C4: 16 | D4: 112 | E4: 52 | M4: Total Frames: | N4: 800
A5: 4 | B5: 0.027019 | C5: 41 | D5: 736 | E5: 170 | I5: Max Delta Total | J5: =MAX(B:B) -> 0.215598
A6: 5 | B6: 0.00989 | C6: 54 | D6: 592 | E6: 170 | I6: Max Delta Saturated: | J6: =MAX(B277:B801) -> 0.215598
A7: 6 | B7: 0.010505 | C7: 58 | D7: 232 | E7: 66
A8: 7 | B8: 0.011614 | C8: 66 | D8: 512 | E8: 134 | I8: Min Delta Total | J8: =MIN(B:B) -> 0.004458
A9: 8 | B9: 0.010546 | C9: 70 | D9: 280 | E9: 80 | I9: Min Delta Saturated | J9: =MIN(B277:B801) -> 0.191605
A10: 9 | B10: 0.010695 | C10: 74 | D10: 296 | E10: 80
A11: 10 | B11: 0.011236 | C11: 83 | D11: 648 | E11: 178 | I11: Average Particle Count Saturated: | J11: =AVERAGE(C277:C801) -> 3088.9562
A12: 11 | B12: 0.018807 | C12: 87 | D12: 348 | E12: 104
A13: 12 | B13: 0.008223 | C13: 95 | D13: 744 | E13: 191 | I13: Channel Collisions Saturated: | J13: =AVERAGE(D277:D801) -> 98981.371
A14: 13 | B14: 0.010202 | C14: 99 | D14: 396 | E14: 109
A15: 14 | B15: 0.010006 | C15: 104 | D15: 416 | E15: 96 | I15: Sphere Collisions Saturated: | J15: =AVERAGE(E277:E801) -> 22918.922
A16: 15 | B16: 0.009049 | C16: 112 | D16: 880 | E16: 244
A17: 16 | B17: 0.010194 | C17: 116 | D17: 464 | E17: 131
A18: 17 | B18: 0.009795 | C18: 120 | D18: 480 | E18: 129
A19: 18 | B19: 0.009117 | C19: 124 | D19: 496 | E19: 126
A20: 19 | B20: 0.00992 | C20: 129 | D20: 516 | E20: 155
A21: 20 | B21: 0.009111 | C21: 133 | D21: 532 | E21: 166
A22: 21 | B22: 0.009657 | C22: 137 | D22: 548 | E22: 180
A23: 22 | B23: 0.009085 | C23: 145 | D23: 1144 | E23: 343
A24: 23 | B24: 0.009605 | C24: 149 | D24: 596 | E24: 192
A25: 24 | B25: 0.010008 | C25: 154 | D25: 616 | E25: 194
A26: 25 | B26: 0.009042 | C26: 158 | D26: 632 | E26: 200
A27: 26 | B27: 0.02213 | C27: 162 | D27: 648 | E27: 198
... A801: 800 | B801: 0.193319 | C801: 3090 | D801: 99000 | E801: 22327

Sheet UniformGrid_300_run5
A1: Frame | B1: DeltaTime | C1: ParticleCount | D1: ChannelCollisions | E1: SphereCollisions
A2: 1 | B2: 0.02 | C2: 0 | D2: 0 | E2: 0 | I2: Average Delta Total: | J2: =AVERAGE(B:B) -> 0.067079158 | M2: Frame Saturation: | N2: 510
A3: 2 | B3: 0.02 | C3: 5 | D3: 28 | E3: 3 | I3: Average Delta Saturated: | J3: =AVERAGE(B511:B1601) -> 0.090210059
A4: 3 | B4: 0.036596 | C4: 10 | D4: 68 | E4: 18 | M4: Total Frames: | N4: 1600
A5: 4 | B5: 0.010227 | C5: 22 | D5: 344 | E5: 71 | I5: Max Delta Total | J5: =MAX(B:B) -> 0.108933
A6: 5 | B6: 0.006695 | C6: 25 | D6: 100 | E6: 26 | I6: Max Delta Saturated: | J6: =MAX(B511:B1601) -> 0.108933
A7: 6 | B7: 0.009562 | C7: 27 | D7: 108 | E7: 21
A8: 7 | B8: 0.007453 | C8: 30 | D8: 120 | E8: 22 | I8: Min Delta Total | J8: =MIN(B:B) -> 0.00387
A9: 8 | B9: 0.012574 | C9: 32 | D9: 128 | E9: 30 | I9: Min Delta Saturated | J9: =MIN(B511:B1601) -> 0.086923
A10: 9 | B10: 0.008223 | C10: 35 | D10: 140 | E10: 27
A11: 10 | B11: 0.007357 | C11: 37 | D11: 148 | E11: 32 | I11: Average Particle Count Saturated: | J11: =AVERAGE(C511:C1601) -> 1843.4803
A12: 11 | B12: 0.007595 | C12: 40 | D12: 160 | E12: 31
A13: 12 | B13: 0.007612 | C13: 42 | D13: 168 | E13: 33 | I13: Channel Collisions Saturated: | J13: =AVERAGE(D511:D1601) -> 59063.604
A14: 13 | B14: 0.008156 | C14: 45 | D14: 180 | E14: 36
A15: 14 | B15: 0.00748 | C15: 47 | D15: 188 | E15: 30 | I15: Sphere Collisions Saturated: | J15: =AVERAGE(E511:E1601) -> 9946.451
A16: 15 | B16: 0.007541 | C16: 50 | D16: 200 | E16: 42
A17: 16 | B17: 0.008018 | C17: 52 | D17: 208 | E17: 37
A18: 17 | B18: 0.007635 | C18: 55 | D18: 220 | E18: 46
A19: 18 | B19: 0.008358 | C19: 57 | D19: 228 | E19: 50
A20: 19 | B20: 0.006004 | C20: 60 | D20: 240 | E20: 50
A21: 20 | B21: 0.00648 | C21: 60 | D21: 0 | E21: 0
A22: 21 | B22: 0.005991 | C22: 62 | D22: 248 | E22: 54
A23: 22 | B23: 0.006123 | C23: 65 | D23: 260 | E23: 58
A24: 23 | B24: 0.006444 | C24: 67 | D24: 268 | E24: 56
A25: 24 | B25: 0.005914 | C25: 67 | D25: 0 | E25: 0
A26: 25 | B26: 0.00648 | C26: 70 | D26: 280 | E26: 50
A27: 26 | B27: 0.006607 | C27: 72 | D27: 288 | E27: 56
... A1601: 1600 | B1601: 0.091118 | C1601: 1844 | D1601: 59064 | E1601: 10090

Sheet UniformGrid_300_run4
A1: Frame | B1: DeltaTime | C1: ParticleCount | D1: ChannelCollisions | E1: SphereCollisions
A2: 1 | B2: 0.02 | C2: 0 | D2: 0 | E2: 0 | I2: Average Delta Total: | J2: =AVERAGE(B:B) -> 0.067223149 | M2: Frame Saturation: | N2: 504
A3: 2 | B3: 0.02 | C3: 5 | D3: 28 | E3: 3 | I3: Average Delta Saturated: | J3: =AVERAGE(B505:B1601) -> 0.089924562
A4: 3 | B4: 0.049887 | C4: 10 | D4: 68 | E4: 18 | M4: Total Frames: | N4: 1600
A5: 4 | B5: 0.011026 | C5: 25 | D5: 444 | E5: 97 | I5: Max Delta Total | J5: =MAX(B:B) -> 0.111276
A6: 5 | B6: 0.006882 | C6: 30 | D6: 228 | E6: 43 | I6: Max Delta Saturated: | J6: =MAX(B505:B1601) -> 0.111276
A7: 6 | B7: 0.007618 | C7: 30 | D7: 0 | E7: 0
A8: 7 | B8: 0.00919 | C8: 32 | D8: 128 | E8: 30 | I8: Min Delta Total | J8: =MIN(B:B) -> 0.003996
A9: 8 | B9: 0.007635 | C9: 35 | D9: 140 | E9: 27 | I9: Min Delta Saturated | J9: =MIN(B505:B1601) -> 0.08618
A10: 9 | B10: 0.008411 | C10: 37 | D10: 148 | E10: 32
A11: 10 | B11: 0.00777 | C11: 40 | D11: 160 | E11: 31 | I11: Average Particle Count Saturated: | J11: =AVERAGE(C505:C1601) -> 1842.9945
A12: 11 | B12: 0.00829 | C12: 42 | D12: 168 | E12: 33
A13: 12 | B13: 0.007659 | C13: 45 | D13: 180 | E13: 36 | I13: Channel Collisions Saturated: | J13: =AVERAGE(D505:D1601) -> 59063.431
A14: 13 | B14: 0.008062 | C14: 47 | D14: 188 | E14: 30
A15: 14 | B15: 0.007447 | C15: 50 | D15: 200 | E15: 42 | I15: Sphere Collisions Saturated: | J15: =AVERAGE(E505:E1601) -> 9946.8578
A16: 15 | B16: 0.008028 | C16: 52 | D16: 208 | E16: 37
A17: 16 | B17: 0.008343 | C17: 55 | D17: 220 | E17: 46
A18: 17 | B18: 0.00791 | C18: 57 | D18: 228 | E18: 50
A19: 18 | B19: 0.005991 | C19: 60 | D19: 240 | E19: 50
A20: 19 | B20: 0.006088 | C20: 62 | D20: 248 | E20: 54
A21: 20 | B21: 0.006985 | C21: 62 | D21: 0 | E21: 0
A22: 21 | B22: 0.006156 | C22: 65 | D22: 260 | E22: 58
A23: 22 | B23: 0.006694 | C23: 67 | D23: 268 | E23: 56
A24: 23 | B24: 0.006094 | C24: 70 | D24: 280 | E24: 50
A25: 24 | B25: 0.006245 | C25: 72 | D25: 288 | E25: 56
A26: 25 | B26: 0.006493 | C26: 72 | D26: 0 | E26: 0
A27: 26 | B27: 0.006165 | C27: 75 | D27: 300 | E27: 55
... A1601: 1600 | B1601: 0.086485 | C1601: 1840 | D1601: 58996 | E1601: 9835

Sheet UniformGrid_300_run3
A1: Frame | B1: DeltaTime | C1: ParticleCount | D1: ChannelCollisions | E1: SphereCollisions
A2: 1 | B2: 0.02 | C2: 0 | D2: 0 | E2: 0 | I2: Average Delta Total: | J2: =AVERAGE(B:B) -> 0.066708999 | M2: Frame Saturation: | N2: 504
A3: 2 | B3: 0.02 | C3: 5 | D3: 28 | E3: 3 | I3: Average Delta Saturated: | J3: =AVERAGE(B505:B1601) -> 0.08932891
A4: 3 | B4: 0.046143 | C4: 10 | D4: 68 | E4: 18 | M4: Total Frames: | N4: 1600
A5: 4 | B5: 0.015967 | C5: 25 | D5: 444 | E5: 97 | I5: Max Delta Total | J5: =MAX(B:B) -> 0.1072
A6: 5 | B6: 0.006779 | C6: 30 | D6: 228 | E6: 43 | I6: Max Delta Saturated: | J6: =MAX(B505:B1601) -> 0.1072
A7: 6 | B7: 0.010185 | C7: 32 | D7: 128 | E7: 30
A8: 7 | B8: 0.007402 | C8: 35 | D8: 140 | E8: 27 | I8: Min Delta Total | J8: =MIN(B:B) -> 0.004114
A9: 8 | B9: 0.011054 | C9: 37 | D9: 148 | E9: 32 | I9: Min Delta Saturated | J9: =MIN(B505:B1601) -> 0.085248
A10: 9 | B10: 0.007587 | C10: 40 | D10: 160 | E10: 31
A11: 10 | B11: 0.008205 | C11: 42 | D11: 168 | E11: 33 | I11: Average Particle Count Saturated: | J11: =AVERAGE(C505:C1601) -> 1843.4731
A12: 11 | B12: 0.007637 | C12: 45 | D12: 180 | E12: 36
A13: 12 | B13: 0.008058 | C13: 47 | D13: 188 | E13: 30 | I13: Channel Collisions Saturated: | J13: =AVERAGE(D505:D1601) -> 59063.409
A14: 13 | B14: 0.007822 | C14: 50 | D14: 200 | E14: 42
A15: 14 | B15: 0.008149 | C15: 52 | D15: 208 | E15: 37 | I15: Sphere Collisions Saturated: | J15: =AVERAGE(E505:E1601) -> 9947.1085
A16: 15 | B16: 0.009053 | C16: 55 | D16: 220 | E16: 46
A17: 16 | B17: 0.010581 | C17: 57 | D17: 228 | E17: 50
A18: 17 | B18: 0.007692 | C18: 60 | D18: 240 | E18: 50
A19: 18 | B19: 0.00821 | C19: 62 | D19: 248 | E19: 54
A20: 19 | B20: 0.007521 | C20: 65 | D20: 260 | E20: 58
A21: 20 | B21: 0.00795 | C21: 67 | D21: 268 | E21: 56
A22: 21 | B22: 0.007716 | C22: 70 | D22: 280 | E22: 50
A23: 22 | B23: 0.008067 | C23: 72 | D23: 288 | E23: 56
A24: 23 | B24: 0.007388 | C24: 75 | D24: 300 | E24: 55
A25: 24 | B25: 0.007985 | C25: 77 | D25: 308 | E25: 60
A26: 25 | B26: 0.007671 | C26: 80 | D26: 320 | E26: 51
A27: 26 | B27: 0.007849 | C27: 80 | D27: 0 | E27: 0
... A1601: 1600 | B1601: 0.08829 | C1601: 1840 | D1601: 58988 | E1601: 10080

Sheet UniformGrid_300_run2
A1: Frame | B1: DeltaTime | C1: ParticleCount | D1: ChannelCollisions | E1: SphereCollisions
A2: 1 | B2: 0.02 | C2: 0 | D2: 0 | E2: 0 | I2: Average Delta Total: | J2: =AVERAGE(B:B) -> 0.067139379 | M2: Frame Saturation: | N2: 504
A3: 2 | B3: 0.02 | C3: 5 | D3: 28 | E3: 3 | I3: Average Delta Saturated: | J3: =AVERAGE(B505:B1601) -> 0.089863082
A4: 3 | B4: 0.051589 | C4: 10 | D4: 68 | E4: 18 | M4: Total Frames: | N4: 1600
A5: 4 | B5: 0.008556 | C5: 25 | D5: 444 | E5: 97 | I5: Max Delta Total | J5: =MAX(B:B) -> 0.112788
A6: 5 | B6: 0.007887 | C6: 30 | D6: 228 | E6: 43 | I6: Max Delta Saturated: | J6: =MAX(B505:B1601) -> 0.112788
A7: 6 | B7: 0.010572 | C7: 30 | D7: 0 | E7: 0
A8: 7 | B8: 0.008086 | C8: 35 | D8: 268 | E8: 57 | I8: Min Delta Total | J8: =MIN(B:B) -> 0.004118
A9: 8 | B9: 0.009042 | C9: 37 | D9: 148 | E9: 32 | I9: Min Delta Saturated | J9: =MIN(B505:B1601) -> 0.086487
A10: 9 | B10: 0.007975 | C10: 40 | D10: 160 | E10: 31
A11: 10 | B11: 0.007554 | C11: 42 | D11: 168 | E11: 33 | I11: Average Particle Count Saturated: | J11: =AVERAGE(C505:C1601) -> 1843.0036
A12: 11 | B12: 0.007384 | C12: 45 | D12: 180 | E12: 36
A13: 12 | B13: 0.007714 | C13: 47 | D13: 188 | E13: 30 | I13: Channel Collisions Saturated: | J13: =AVERAGE(D505:D1601) -> 59063.42
A14: 13 | B14: 0.008327 | C14: 47 | D14: 0 | E14: 0
A15: 14 | B15: 0.008406 | C15: 50 | D15: 200 | E15: 42 | I15: Sphere Collisions Saturated: | J15: =AVERAGE(E505:E1601) -> 9947.0219
A16: 15 | B16: 0.007318 | C16: 52 | D16: 208 | E16: 37
A17: 16 | B17: 0.009433 | C17: 55 | D17: 220 | E17: 46
A18: 17 | B18: 0.010203 | C18: 57 | D18: 228 | E18: 50
A19: 18 | B19: 0.007469 | C19: 62 | D19: 488 | E19: 104
A20: 19 | B20: 0.007475 | C20: 65 | D20: 260 | E20: 58
A21: 20 | B21: 0.007802 | C21: 65 | D21: 0 | E21: 0
A22: 21 | B22: 0.00759 | C22: 67 | D22: 268 | E22: 56
A23: 22 | B23: 0.008151 | C23: 70 | D23: 280 | E23: 50
A24: 23 | B24: 0.00741 | C24: 72 | D24: 288 | E24: 56
A25: 24 | B25: 0.007938 | C25: 75 | D25: 300 | E25: 55
A26: 25 | B26: 0.007691 | C26: 77 | D26: 308 | E26: 60
A27: 26 | B27: 0.006695 | C27: 80 | D27: 320 | E27: 51
... A1601: 1600 | B1601: 0.089992 | C1601: 1842 | D1601: 58976 | E1601: 9751

Sheet UniformGrid_300_run1
A1: Frame | B1: DeltaTime | C1: ParticleCount | D1: ChannelCollisions | E1: SphereCollisions
A2: 1 | B2: 0.02 | C2: 0 | D2: 0 | E2: 0 | I2: Average Delta Total: | J2: =AVERAGE(B:B) -> 0.068412902 | M2: Frame Saturation: | N2: 497
A3: 2 | B3: 0.02 | C3: 5 | D3: 28 | E3: 3 | I3: Average Delta Saturated: | J3: =AVERAGE(B498:B1601) -> 0.091086285
A4: 3 | B4: 0.045987 | C4: 10 | D4: 68 | E4: 18 | M4: Total Frames: | N4: 1600
A5: 4 | B5: 0.009095 | C5: 25 | D5: 444 | E5: 97 | I5: Max Delta Total | J5: =MAX(B:B) -> 0.104573
A6: 5 | B6: 0.00726 | C6: 27 | D6: 108 | E6: 21 | I6: Max Delta Saturated: | J6: =MAX(B498:B1601) -> 0.104573
A7: 6 | B7: 0.01442 | C7: 30 | D7: 120 | E7: 22
A8: 7 | B8: 0.007641 | C8: 35 | D8: 268 | E8: 57 | I8: Min Delta Total | J8: =MIN(B:B) -> 0.004208
A9: 8 | B9: 0.014031 | C9: 35 | D9: 0 | E9: 0 | I9: Min Delta Saturated | J9: =MIN(B498:B1601) -> 0.087669
A10: 9 | B10: 0.00764 | C10: 40 | D10: 308 | E10: 63
A11: 10 | B11: 0.008184 | C11: 42 | D11: 168 | E11: 33 | I11: Average Particle Count Saturated: | J11: =AVERAGE(C498:C1601) -> 1842.9909
A12: 11 | B12: 0.007618 | C12: 45 | D12: 180 | E12: 36
A13: 12 | B13: 0.007875 | C13: 47 | D13: 188 | E13: 30 | I13: Channel Collisions Saturated: | J13: =AVERAGE(D498:D1601) -> 59062.986
A14: 13 | B14: 0.007767 | C14: 50 | D14: 200 | E14: 42
A15: 14 | B15: 0.008191 | C15: 52 | D15: 208 | E15: 37 | I15: Sphere Collisions Saturated: | J15: =AVERAGE(E498:E1601) -> 9947.5661
A16: 15 | B16: 0.009064 | C16: 55 | D16: 220 | E16: 46
A17: 16 | B17: 0.010536 | C17: 57 | D17: 228 | E17: 50
A18: 17 | B18: 0.007688 | C18: 60 | D18: 240 | E18: 50
A19: 18 | B19: 0.008195 | C19: 62 | D19: 248 | E19: 54
A20: 19 | B20: 0.007596 | C20: 65 | D20: 260 | E20: 58
A21: 20 | B21: 0.007874 | C21: 67 | D21: 268 | E21: 56
A22: 21 | B22: 0.007591 | C22: 70 | D22: 280 | E22: 50
A23: 22 | B23: 0.008297 | C23: 72 | D23: 288 | E23: 56
A24: 23 | B24: 0.007463 | C24: 75 | D24: 300 | E24: 55
A25: 24 | B25: 0.008152 | C25: 77 | D25: 308 | E25: 60
A26: 25 | B26: 0.007646 | C26: 80 | D26: 320 | E26: 51
A27: 26 | B27: 0.005873 | C27: 82 | D27: 328 | E27: 50
... A1601: 1600 | B1601: 0.089325 | C1601: 1842 | D1601: 58984 | E1601: 9980

Sheet UniformGrid_100_run5
A1: Frame | B1: DeltaTime | C1: ParticleCount | D1: ChannelCollisions | E1: SphereCollisions
A2: 1 | B2: 0.02 | C2: 0 | D2: 0 | E2: 0 | I2: Average Delta Total: | J2: =AVERAGE(B:B) -> 0.00761856 | M2: Frame Saturation: | N2: 982
A3: 2 | B3: 0.02 | C3: 1 | D3: 4 | E3: 0 | I3: Average Delta Saturated: | J3: =AVERAGE(B893:B1601) -> 0.0091719379
A4: 3 | B4: 0.049069 | C4: 3 | D4: 20 | E4: 1 | M4: Total Frames: | N4: 1600
A5: 4 | B5: 0.008068 | C5: 8 | D5: 140 | E5: 16 | I5: Max Delta Total | J5: =MAX(B:B) -> 0.049069
A6: 5 | B6: 0.00733 | C6: 9 | D6: 36 | E6: 4 | I6: Max Delta Saturated: | J6: =MAX(B893:B1601) -> 0.013157
A7: 6 | B7: 0.00931 | C7: 10 | D7: 40 | E7: 4
A8: 7 | B8: 0.007576 | C8: 10 | D8: 40 | E8: 5 | I8: Min Delta Total | J8: =MIN(B:B) -> 0.004236
A9: 8 | B9: 0.011615 | C9: 11 | D9: 44 | E9: 5 | I9: Min Delta Saturated | J9: =MIN(B893:B1601) -> 0.00487
A10: 9 | B10: 0.007651 | C10: 12 | D10: 48 | E10: 4
A11: 10 | B11: 0.008081 | C11: 13 | D11: 52 | E11: 4 | I11: Average Particle Count Saturated: | J11: =AVERAGE(C893:C1601) -> 598.0141
A12: 11 | B12: 0.007336 | C12: 14 | D12: 56 | E12: 3
A13: 12 | B13: 0.007898 | C13: 15 | D13: 60 | E13: 5 | I13: Channel Collisions Saturated: | J13: =AVERAGE(D893:D1601) -> 2635.6164
A14: 13 | B14: 0.007694 | C14: 15 | D14: 60 | E14: 7
A15: 14 | B15: 0.008009 | C15: 16 | D15: 64 | E15: 7 | I15: Sphere Collisions Saturated: | J15: =AVERAGE(E893:E1601) -> 370.28914
A16: 15 | B16: 0.007461 | C16: 17 | D16: 68 | E16: 10
A17: 16 | B17: 0.00916 | C17: 18 | D17: 72 | E17: 10
A18: 17 | B18: 0.008792 | C18: 19 | D18: 76 | E18: 9
A19: 18 | B19: 0.007937 | C19: 20 | D19: 80 | E19: 8
A20: 19 | B20: 0.007503 | C20: 20 | D20: 80 | E20: 6
A21: 20 | B21: 0.0078 | C21: 21 | D21: 84 | E21: 3
A22: 21 | B22: 0.007492 | C22: 22 | D22: 88 | E22: 6
A23: 22 | B23: 0.008252 | C23: 23 | D23: 92 | E23: 10
A24: 23 | B24: 0.007637 | C24: 24 | D24: 96 | E24: 10
A25: 24 | B25: 0.007426 | C25: 25 | D25: 100 | E25: 11
A26: 25 | B26: 0.008052 | C26: 25 | D26: 100 | E26: 11
A27: 26 | B27: 0.007637 | C27: 26 | D27: 104 | E27: 13
... A1601: 1600 | B1601: 0.010561 | C1601: 600 | D1601: 2404 | E1601: 334

Sheet UniformGrid_100_run4
A1: Frame | B1: DeltaTime | C1: ParticleCount | D1: ChannelCollisions | E1: SphereCollisions
A2: 1 | B2: 0.02 | C2: 0 | D2: 0 | E2: 0 | I2: Average Delta Total: | J2: =AVERAGE(B:B) -> 0.0076195525 | M2: Frame Saturation: | N2: 986
A3: 2 | B3: 0.02 | C3: 1 | D3: 4 | E3: 0 | I3: Average Delta Saturated: | J3: =AVERAGE(B987:B1601) -> 0.0092826341
A4: 3 | B4: 0.037774 | C4: 3 | D4: 20 | E4: 1 | M4: Total Frames: | N4: 1600
A5: 4 | B5: 0.00962 | C5: 7 | D5: 108 | E5: 13 | I5: Max Delta Total | J5: =MAX(B:B) -> 0.037774
A6: 5 | B6: 0.007586 | C6: 8 | D6: 32 | E6: 3 | I6: Max Delta Saturated: | J6: =MAX(B987:B1601) -> 0.013495
A7: 6 | B7: 0.009845 | C7: 9 | D7: 36 | E7: 4
A8: 7 | B8: 0.007859 | C8: 10 | D8: 40 | E8: 4 | I8: Min Delta Total | J8: =MIN(B:B) -> 0.004138
A9: 8 | B9: 0.011068 | C9: 10 | D9: 40 | E9: 5 | I9: Min Delta Saturated | J9: =MIN(B987:B1601) -> 0.007302
A10: 9 | B10: 0.008288 | C10: 11 | D10: 44 | E10: 5
A11: 10 | B11: 0.007472 | C11: 12 | D11: 48 | E11: 4 | I11: Average Particle Count Saturated: | J11: =AVERAGE(C987:C1601) -> 599.6813
A12: 11 | B12: 0.008158 | C12: 13 | D12: 52 | E12: 4
A13: 12 | B13: 0.007568 | C13: 14 | D13: 56 | E13: 3 | I13: Channel Collisions Saturated: | J13: =AVERAGE(D987:D1601) -> 2675.4211
A14: 13 | B14: 0.008462 | C14: 15 | D14: 60 | E14: 5
A15: 14 | B15: 0.007374 | C15: 15 | D15: 60 | E15: 7 | I15: Sphere Collisions Saturated: | J15: =AVERAGE(E987:E1601) -> 372.88293
A16: 15 | B16: 0.007738 | C16: 16 | D16: 64 | E16: 7
A17: 16 | B17: 0.007748 | C17: 17 | D17: 68 | E17: 10
A18: 17 | B18: 0.010247 | C18: 18 | D18: 72 | E18: 10
A19: 18 | B19: 0.009815 | C19: 19 | D19: 76 | E19: 9
A20: 19 | B20: 0.008265 | C20: 20 | D20: 80 | E20: 8
A21: 20 | B21: 0.007532 | C21: 20 | D21: 80 | E21: 6
A22: 21 | B22: 0.008207 | C22: 21 | D22: 84 | E22: 3
A23: 22 | B23: 0.007255 | C23: 22 | D23: 88 | E23: 6
A24: 23 | B24: 0.008152 | C24: 23 | D24: 92 | E24: 10
A25: 24 | B25: 0.007368 | C25: 24 | D25: 96 | E25: 10
A26: 25 | B26: 0.008015 | C26: 25 | D26: 100 | E26: 11
A27: 26 | B27: 0.007581 | C27: 25 | D27: 100 | E27: 11
... A1601: 1600 | B1601: 0.008973 | C1601: 600 | D1601: 2404 | E1601: 334

Sheet UniformGrid_100_run3
A1: Frame | B1: DeltaTime | C1: ParticleCount | D1: ChannelCollisions | E1: SphereCollisions
A2: 1 | B2: 0.02 | C2: 0 | D2: 0 | E2: 0 | I2: Average Delta Total: | J2: =AVERAGE(B:B) -> 0.007622725 | M2: Frame Saturation: | N2: 989
A3: 2 | B3: 0.02 | C3: 1 | D3: 4 | E3: 0 | I3: Average Delta Saturated: | J3: =AVERAGE(B990:B1601) -> 0.0093368317
A4: 3 | B4: 0.037228 | C4: 3 | D4: 20 | E4: 1 | M4: Total Frames: | N4: 1600
A5: 4 | B5: 0.010271 | C5: 7 | D5: 108 | E5: 13 | I5: Max Delta Total | J5: =MAX(B:B) -> 0.037228
A6: 5 | B6: 0.007826 | C6: 8 | D6: 32 | E6: 3 | I6: Max Delta Saturated: | J6: =MAX(B990:B1601) -> 0.014282
A7: 6 | B7: 0.007746 | C7: 9 | D7: 36 | E7: 4
A8: 7 | B8: 0.007941 | C8: 10 | D8: 40 | E8: 4 | I8: Min Delta Total | J8: =MIN(B:B) -> 0.004304
A9: 8 | B9: 0.008752 | C9: 10 | D9: 40 | E9: 5 | I9: Min Delta Saturated | J9: =MIN(B990:B1601) -> 0.007245
A10: 9 | B10: 0.007814 | C10: 11 | D10: 44 | E10: 5
A11: 10 | B11: 0.00758 | C11: 12 | D11: 48 | E11: 4 | I11: Average Particle Count Saturated: | J11: =AVERAGE(C990:C1601) -> 599.69608
A12: 11 | B12: 0.008023 | C12: 13 | D12: 52 | E12: 4
A13: 12 | B13: 0.007589 | C13: 14 | D13: 56 | E13: 3 | I13: Channel Collisions Saturated: | J13: =AVERAGE(D990:D1601) -> 2692.4641
A14: 13 | B14: 0.00813 | C14: 15 | D14: 60 | E14: 5
A15: 14 | B15: 0.007608 | C15: 15 | D15: 60 | E15: 7 | I15: Sphere Collisions Saturated: | J15: =AVERAGE(E990:E1601) -> 375.25817
A16: 15 | B16: 0.008017 | C16: 15 | D16: 0 | E16: 0
A17: 16 | B17: 0.007532 | C17: 16 | D17: 64 | E17: 7
A18: 17 | B18: 0.008313 | C18: 17 | D18: 68 | E18: 10
A19: 18 | B19: 0.009851 | C19: 18 | D19: 72 | E19: 10
A20: 19 | B20: 0.009319 | C20: 20 | D20: 156 | E20: 17
A21: 20 | B21: 0.007514 | C21: 20 | D21: 80 | E21: 6
A22: 21 | B22: 0.007853 | C22: 21 | D22: 84 | E22: 3
A23: 22 | B23: 0.007518 | C23: 21 | D23: 0 | E23: 0
A24: 23 | B24: 0.00818 | C24: 22 | D24: 88 | E24: 6
A25: 24 | B25: 0.007691 | C25: 23 | D25: 92 | E25: 10
A26: 25 | B26: 0.007651 | C26: 24 | D26: 96 | E26: 10
A27: 26 | B27: 0.008098 | C27: 25 | D27: 100 | E27: 11
... A1601: 1600 | B1601: 0.012418 | C1601: 601 | D1601: 4808 | E1601: 669

Sheet UniformGrid_100_run2
A1: Frame | B1: DeltaTime | C1: ParticleCount | D1: ChannelCollisions | E1: SphereCollisions
A2: 1 | B2: 0.02 | C2: 0 | D2: 0 | E2: 0 | I2: Average Delta Total: | J2: =AVERAGE(B:B) -> 0.0076921162 | M2: Frame Saturation: | N2: 973
A3: 2 | B3: 0.02 | C3: 1 | D3: 4 | E3: 0 | I3: Average Delta Saturated: | J3: =AVERAGE(B974:B1601) -> 0.0092802229
A4: 3 | B4: 0.039155 | C4: 3 | D4: 20 | E4: 1 | M4: Total Frames: | N4: 1600
A5: 4 | B5: 0.010166 | C5: 7 | D5: 108 | E5: 13 | I5: Max Delta Total | J5: =MAX(B:B) -> 0.039155
A6: 5 | B6: 0.007099 | C6: 8 | D6: 32 | E6: 3 | I6: Max Delta Saturated: | J6: =MAX(B974:B1601) -> 0.013394
A7: 6 | B7: 0.010697 | C7: 9 | D7: 36 | E7: 4
A8: 7 | B8: 0.007948 | C8: 10 | D8: 40 | E8: 4 | I8: Min Delta Total | J8: =MIN(B:B) -> 0.004265
A9: 8 | B9: 0.013524 | C9: 10 | D9: 40 | E9: 5 | I9: Min Delta Saturated | J9: =MIN(B974:B1601) -> 0.007294
A10: 9 | B10: 0.00764 | C10: 12 | D10: 92 | E10: 9
A11: 10 | B11: 0.007904 | C11: 13 | D11: 52 | E11: 4 | I11: Average Particle Count Saturated: | J11: =AVERAGE(C974:C1601) -> 599.71815
A12: 11 | B12: 0.007345 | C12: 14 | D12: 56 | E12: 3
A13: 12 | B13: 0.007831 | C13: 15 | D13: 60 | E13: 5 | I13: Channel Collisions Saturated: | J13: =AVERAGE(D974:D1601) -> 2673.7197
A14: 13 | B14: 0.007211 | C14: 15 | D14: 60 | E14: 7
A15: 14 | B15: 0.007135 | C15: 15 | D15: 0 | E15: 0 | I15: Sphere Collisions Saturated: | J15: =AVERAGE(E974:E1601) -> 372.55573
A16: 15 | B16: 0.008034 | C16: 16 | D16: 64 | E16: 7
A17: 16 | B17: 0.007289 | C17: 17 | D17: 68 | E17: 10
A18: 17 | B18: 0.009907 | C18: 18 | D18: 72 | E18: 10
A19: 18 | B19: 0.00986 | C19: 19 | D19: 76 | E19: 9
A20: 19 | B20: 0.007262 | C20: 20 | D20: 160 | E20: 14
A21: 20 | B21: 0.007191 | C21: 20 | D21: 0 | E21: 0
A22: 21 | B22: 0.007454 | C22: 21 | D22: 84 | E22: 3
A23: 22 | B23: 0.007221 | C23: 22 | D23: 88 | E23: 6
A24: 23 | B24: 0.007952 | C24: 23 | D24: 92 | E24: 10
A25: 24 | B25: 0.007142 | C25: 24 | D25: 96 | E25: 10
A26: 25 | B26: 0.007812 | C26: 25 | D26: 100 | E26: 11
A27: 26 | B27: 0.007317 | C27: 25 | D27: 100 | E27: 11
... A1601: 1600 | B1601: 0.007706 | C1601: 602 | D1601: 2412 | E1601: 339

Sheet UniformGrid_100_run1
A1: Frame | B1: DeltaTime | C1: ParticleCount | D1: ChannelCollisions | E1: SphereCollisions
A2: 1 | B2: 0.02 | C2: 0 | D2: 0 | E2: 0 | I2: Average Delta Total: | J2: =AVERAGE(B:B) -> 0.01035253 | M2: Frame Saturation: | N2: 877
A3: 2 | B3: 0.02 | C3: 1 | D3: 4 | E3: 0 | I3: Average Delta Saturated: | J3: =AVERAGE(B878:B1601) -> 0.013923207
A4: 3 | B4: 0.049734 | C4: 3 | D4: 20 | E4: 1 | M4: Total Frames: | N4: 1600
A5: 4 | B5: 0.018257 | C5: 8 | D5: 140 | E5: 16 | I5: Max Delta Total | J5: =MAX(B:B) -> 0.049734
A6: 5 | B6: 0.0096 | C6: 10 | D6: 76 | E6: 8 | I6: Max Delta Saturated: | J6: =MAX(B878:B1601) -> 0.026095
A7: 6 | B7: 0.010402 | C7: 11 | D7: 84 | E7: 10
A8: 7 | B8: 0.011414 | C8: 12 | D8: 48 | E8: 4 | I8: Min Delta Total | J8: =MIN(B:B) -> 0.004118
A9: 8 | B9: 0.009455 | C9: 13 | D9: 52 | E9: 4 | I9: Min Delta Saturated | J9: =MIN(B878:B1601) -> 0.009414
A10: 9 | B10: 0.010759 | C10: 14 | D10: 56 | E10: 3
A11: 10 | B11: 0.010316 | C11: 15 | D11: 120 | E11: 12 | I11: Average Particle Count Saturated: | J11: =AVERAGE(C878:C1601) -> 599.83978
A12: 11 | B12: 0.010284 | C12: 16 | D12: 64 | E12: 7
A13: 12 | B13: 0.018276 | C13: 17 | D13: 68 | E13: 10 | I13: Channel Collisions Saturated: | J13: =AVERAGE(D878:D1601) -> 4015.5801
A14: 13 | B14: 0.009193 | C14: 19 | D14: 148 | E14: 19
A15: 14 | B15: 0.01148 | C15: 20 | D15: 80 | E15: 8 | I15: Sphere Collisions Saturated: | J15: =AVERAGE(E878:E1601) -> 563.05525
A16: 15 | B16: 0.01002 | C16: 21 | D16: 164 | E16: 9
A17: 16 | B17: 0.009673 | C17: 22 | D17: 88 | E17: 6
A18: 17 | B18: 0.010275 | C18: 23 | D18: 92 | E18: 10
A19: 18 | B19: 0.010548 | C19: 24 | D19: 96 | E19: 10
A20: 19 | B20: 0.010052 | C20: 25 | D20: 200 | E20: 22
A21: 20 | B21: 0.009552 | C21: 26 | D21: 104 | E21: 13
A22: 21 | B22: 0.010054 | C22: 27 | D22: 108 | E22: 8
A23: 22 | B23: 0.009587 | C23: 28 | D23: 112 | E23: 6
A24: 23 | B24: 0.006737 | C24: 29 | D24: 116 | E24: 9
A25: 24 | B25: 0.005391 | C25: 30 | D25: 120 | E25: 11
A26: 25 | B26: 0.00551 | C26: 30 | D26: 120 | E26: 12
A27: 26 | B27: 0.005011 | C27: 30 | D27: 0 | E27: 0
... A1601: 1600 | B1601: 0.013737 | C1601: 600 | D1601: 4808 | E1601: 673

Sheet BatchData
B2: Particles Per Second | C2: 100 | D2: 300 | E2: 500 | G2: Delta Time | H2: 100 | I2: 300 | J2: 500 | M2: Sphere Collisions | N2: 100 | O2: 300 | P2: 500
B3: Average DeltaTime Saturated | C3: =AVERAGE(UniformGrid_100_run5!J3,UniformGrid_100_run4!J3,UniformGrid_100_run3!J3,UniformGrid_100_run2!J3,UniformGrid_100_run1!J3) -> 0.010198967 | D3: =AVERAGE(UniformGrid_300_run5!J3,UniformGrid_300_run4!J3,UniformGrid_300_run3!J3,UniformGrid_300_run2!J3,UniformGrid_300_run1!J3) -> 0.09008258 | E3: =AVERAGE(UniformGrid_500_run5!J3,UniformGrid_500_run4!J3,UniformGrid_500_run3!J3,UniformGrid_500_run2!J3,UniformGrid_500_run1!J3) -> 0.17984224 | H3: =AVERAGE(UniformGrid_100_run1!B2,UniformGrid_100_run2!B2,UniformGrid_100_run3!B2,UniformGrid_100_run4!B2,UniformGrid_100_run5!B2) -> 0.02 | I3: =AVERAGE(UniformGrid_300_run1!B2,UniformGrid_300_run2!B2,UniformGrid_300_run3!B2,UniformGrid_300_run4!B2,UniformGrid_300_run5!B2) -> 0.02 | J3: =AVERAGE(UniformGrid_500_run1!B2,UniformGrid_500_run2!B2,UniformGrid_500_run3!B2,UniformGrid_500_run4!B2,UniformGrid_500_run5!B2) -> 0.02 | N3: =AVERAGE(UniformGrid_100_run1!E2,UniformGrid_100_run2!E2,UniformGrid_100_run3!E2,UniformGrid_100_run4!E2,UniformGrid_100_run5!E2) -> 0 | O3: =AVERAGE(UniformGrid_300_run1!E2,UniformGrid_300_run2!E2,UniformGrid_300_run3!E2,UniformGrid_300_run4!E2,UniformGrid_300_run5!E2) -> 0 | P3: =AVERAGE(UniformGrid_500_run1!E2,UniformGrid_500_run2!E2,UniformGrid_500_run3!E2,UniformGrid_500_run4!E2,UniformGrid_500_run5!E2) -> 0
H4: =AVERAGE(UniformGrid_100_run1!B3,UniformGrid_100_run2!B3,UniformGrid_100_run3!B3,UniformGrid_100_run4!B3,UniformGrid_100_run5!B3) -> 0.02 | I4: =AVERAGE(UniformGrid_300_run1!B3,UniformGrid_300_run2!B3,UniformGrid_300_run3!B3,UniformGrid_300_run4!B3,UniformGrid_300_run5!B3) -> 0.02 | J4: =AVERAGE(UniformGrid_500_run1!B3,UniformGrid_500_run2!B3,UniformGrid_500_run3!B3,UniformGrid_500_run4!B3,UniformGrid_500_run5!B3) -> 0.02 | N4: =AVERAGE(UniformGrid_100_run1!E3,UniformGrid_100_run2!E3,UniformGrid_100_run3!E3,UniformGrid_100_run4!E3,UniformGrid_100_run5!E3) -> 0 | O4: =AVERAGE(UniformGrid_300_run1!E3,UniformGrid_300_run2!E3,UniformGrid_300_run3!E3,UniformGrid_300_run4!E3,UniformGrid_300_run5!E3) -> 3 | P4: =AVERAGE(UniformGrid_500_run1!E3,UniformGrid_500_run2!E3,UniformGrid_500_run3!E3,UniformGrid_500_run4!E3,UniformGrid_500_run5!E3) -> 5
B5: Max Delta Saturated: | C5: =MAX(UniformGrid_100_run5!J6,UniformGrid_100_run4!J6,UniformGrid_100_run3!J6,UniformGrid_100_run2!J6,UniformGrid_100_run1!J6) -> 0.026095 | D5: =MAX(UniformGrid_300_run5!J6,UniformGrid_300_run4!J6,UniformGrid_300_run3!J6,UniformGrid_300_run2!J6,UniformGrid_300_run1!J6) -> 0.112788 | E5: =MAX(UniformGrid_500_run5!J6,UniformGrid_500_run4!J6,UniformGrid_500_run3!J6,UniformGrid_500_run2!J6,UniformGrid_500_run1!J6) -> 0.216296 | H5: =AVERAGE(UniformGrid_100_run1!B4,UniformGrid_100_run2!B4,UniformGrid_100_run3!B4,UniformGrid_100_run4!B4,UniformGrid_100_run5!B4) -> 0.042592 | I5: =AVERAGE(UniformGrid_300_run1!B4,UniformGrid_300_run2!B4,UniformGrid_300_run3!B4,UniformGrid_300_run4!B4,UniformGrid_300_run5!B4) -> 0.0460404 | J5: =AVERAGE(UniformGrid_500_run1!B4,UniformGrid_500_run2!B4,UniformGrid_500_run3!B4,UniformGrid_500_run4!B4,UniformGrid_500_run5!B4) -> 0.0407874 | N5: =AVERAGE(UniformGrid_100_run1!E4,UniformGrid_100_run2!E4,UniformGrid_100_run3!E4,UniformGrid_100_run4!E4,UniformGrid_100_run5!E4) -> 1 | O5: =AVERAGE(UniformGrid_300_run1!E4,UniformGrid_300_run2!E4,UniformGrid_300_run3!E4,UniformGrid_300_run4!E4,UniformGrid_300_run5!E4) -> 18 | P5: =AVERAGE(UniformGrid_500_run1!E4,UniformGrid_500_run2!E4,UniformGrid_500_run3!E4,UniformGrid_500_run4!E4,UniformGrid_500_run5!E4) -> 52
H6: =AVERAGE(UniformGrid_100_run1!B5,UniformGrid_100_run2!B5,UniformGrid_100_run3!B5,UniformGrid_100_run4!B5,UniformGrid_100_run5!B5) -> 0.0112764 | I6: =AVERAGE(UniformGrid_300_run1!B5,UniformGrid_300_run2!B5,UniformGrid_300_run3!B5,UniformGrid_300_run4!B5,UniformGrid_300_run5!B5) -> 0.0109742 | J6: =AVERAGE(UniformGrid_500_run1!B5,UniformGrid_500_run2!B5,UniformGrid_500_run3!B5,UniformGrid_500_run4!B5,UniformGrid_500_run5!B5) -> 0.015037 | N6: =AVERAGE(UniformGrid_100_run1!E5,UniformGrid_100_run2!E5,UniformGrid_100_run3!E5,UniformGrid_100_run4!E5,UniformGrid_100_run5!E5) -> 14.2 | O6: =AVERAGE(UniformGrid_300_run1!E5,UniformGrid_300_run2!E5,UniformGrid_300_run3!E5,UniformGrid_300_run4!E5,UniformGrid_300_run5!E5) -> 91.8 | P6: =AVERAGE(UniformGrid_500_run1!E5,UniformGrid_500_run2!E5,UniformGrid_500_run3!E5,UniformGrid_500_run4!E5,UniformGrid_500_run5!E5) -> 147.2
B7: Min Delta Saturated: | C7: =MIN(UniformGrid_100_run5!J9,UniformGrid_100_run4!J9,UniformGrid_100_run3!J9,UniformGrid_100_run2!J9,UniformGrid_100_run1!J9) -> 0.00487 | D7: =MIN(UniformGrid_300_run5!J9,UniformGrid_300_run4!J9,UniformGrid_300_run3!J9,UniformGrid_300_run2!J9,UniformGrid_300_run1!J9) -> 0.085248 | E7: =MIN(UniformGrid_500_run5!J9,UniformGrid_500_run4!J9,UniformGrid_500_run3!J9,UniformGrid_500_run2!J9,UniformGrid_500_run1!J9) -> 0.171606 | H7: =AVERAGE(UniformGrid_100_run1!B6,UniformGrid_100_run2!B6,UniformGrid_100_run3!B6,UniformGrid_100_run4!B6,UniformGrid_100_run5!B6) -> 0.0078882 | I7: =AVERAGE(UniformGrid_300_run1!B6,UniformGrid_300_run2!B6,UniformGrid_300_run3!B6,UniformGrid_300_run4!B6,UniformGrid_300_run5!B6) -> 0.0071006 | J7: =AVERAGE(UniformGrid_500_run1!B6,UniformGrid_500_run2!B6,UniformGrid_500_run3!B6,UniformGrid_500_run4!B6,UniformGrid_500_run5!B6) -> 0.0084458 | N7: =AVERAGE(UniformGrid_100_run1!E6,UniformGrid_100_run2!E6,UniformGrid_100_run3!E6,UniformGrid_100_run4!E6,UniformGrid_100_run5!E6) -> 4.2 | O7: =AVERAGE(UniformGrid_300_run1!E6,UniformGrid_300_run2!E6,UniformGrid_300_run3!E6,UniformGrid_300_run4!E6,UniformGrid_300_run5!E6) -> 35.2 | P7: =AVERAGE(UniformGrid_500_run1!E6,UniformGrid_500_run2!E6,UniformGrid_500_run3!E6,UniformGrid_500_run4!E6,UniformGrid_500_run5!E6) -> 76.4
H8: =AVERAGE(UniformGrid_100_run1!B7,UniformGrid_100_run2!B7,UniformGrid_100_run3!B7,UniformGrid_100_run4!B7,UniformGrid_100_run5!B7) -> 0.0096 | I8: =AVERAGE(UniformGrid_300_run1!B7,UniformGrid_300_run2!B7,UniformGrid_300_run3!B7,UniformGrid_300_run4!B7,UniformGrid_300_run5!B7) -> 0.0104714 | J8: =AVERAGE(UniformGrid_500_run1!B7,UniformGrid_500_run2!B7,UniformGrid_500_run3!B7,UniformGrid_500_run4!B7,UniformGrid_500_run5!B7) -> 0.0107626 | N8: =AVERAGE(UniformGrid_100_run1!E7,UniformGrid_100_run2!E7,UniformGrid_100_run3!E7,UniformGrid_100_run4!E7,UniformGrid_100_run5!E7) -> 5.2 | O8: =AVERAGE(UniformGrid_300_run1!E7,UniformGrid_300_run2!E7,UniformGrid_300_run3!E7,UniformGrid_300_run4!E7,UniformGrid_300_run5!E7) -> 14.6 | P8: =AVERAGE(UniformGrid_500_run1!E7,UniformGrid_500_run2!E7,UniformGrid_500_run3!E7,UniformGrid_500_run4!E7,UniformGrid_500_run5!E7) -> 57.2
B9: Average Saturation Frame: | C9: =AVERAGE(UniformGrid_100_run1!N2,UniformGrid_100_run2!N2,UniformGrid_100_run3!N2,UniformGrid_100_run4!N2,UniformGrid_100_run5!N2) -> 961.4 | D9: =AVERAGE(UniformGrid_300_run1!N2,UniformGrid_300_run2!N2,UniformGrid_300_run3!N2,UniformGrid_300_run4!N2,UniformGrid_300_run5!N2) -> 503.8 | E9: =AVERAGE(UniformGrid_500_run1!N2,UniformGrid_500_run2!N2,UniformGrid_500_run3!N2,UniformGrid_500_run4!N2,UniformGrid_500_run5!N2) -> 315.6 | H9: =AVERAGE(UniformGrid_100_run1!B8,UniformGrid_100_run2!B8,UniformGrid_100_run3!B8,UniformGrid_100_run4!B8,UniformGrid_100_run5!B8) -> 0.0085476 | I9: =AVERAGE(UniformGrid_300_run1!B8,UniformGrid_300_run2!B8,UniformGrid_300_run3!B8,UniformGrid_300_run4!B8,UniformGrid_300_run5!B8) -> 0.0079544 | J9: =AVERAGE(UniformGrid_500_run1!B8,UniformGrid_500_run2!B8,UniformGrid_500_run3!B8,UniformGrid_500_run4!B8,UniformGrid_500_run5!B8) -> 0.0091124 | N9: =AVERAGE(UniformGrid_100_run1!E8,UniformGrid_100_run2!E8,UniformGrid_100_run3!E8,UniformGrid_100_run4!E8,UniformGrid_100_run5!E8) -> 4.2 | O9: =AVERAGE(UniformGrid_300_run1!E8,UniformGrid_300_run2!E8,UniformGrid_300_run3!E8,UniformGrid_300_run4!E8,UniformGrid_300_run5!E8) -> 38.6 | P9: =AVERAGE(UniformGrid_500_run1!E8,UniformGrid_500_run2!E8,UniformGrid_500_run3!E8,UniformGrid_500_run4!E8,UniformGrid_500_run5!E8) -> 88.4
H10: =AVERAGE(UniformGrid_100_run1!B9,UniformGrid_100_run2!B9,UniformGrid_100_run3!B9,UniformGrid_100_run4!B9,UniformGrid_100_run5!B9) -> 0.0108828 | I10: =AVERAGE(UniformGrid_300_run1!B9,UniformGrid_300_run2!B9,UniformGrid_300_run3!B9,UniformGrid_300_run4!B9,UniformGrid_300_run5!B9) -> 0.0108672 | J10: =AVERAGE(UniformGrid_500_run1!B9,UniformGrid_500_run2!B9,UniformGrid_500_run3!B9,UniformGrid_500_run4!B9,UniformGrid_500_run5!B9) -> 0.0104092 | N10: =AVERAGE(UniformGrid_100_run1!E9,UniformGrid_100_run2!E9,UniformGrid_100_run3!E9,UniformGrid_100_run4!E9,UniformGrid_100_run5!E9) -> 4.8 | O10: =AVERAGE(UniformGrid_300_run1!E9,UniformGrid_300_run2!E9,UniformGrid_300_run3!E9,UniformGrid_300_run4!E9,UniformGrid_300_run5!E9) -> 24.2 | P10: =AVERAGE(UniformGrid_500_run1!E9,UniformGrid_500_run2!E9,UniformGrid_500_run3!E9,UniformGrid_500_run4!E9,UniformGrid_500_run5!E9) -> 66.6
H11: =AVERAGE(UniformGrid_100_run1!B10,UniformGrid_100_run2!B10,UniformGrid_100_run3!B10,UniformGrid_100_run4!B10,UniformGrid_100_run5!B10) -> 0.0084304 | I11: =AVERAGE(UniformGrid_300_run1!B10,UniformGrid_300_run2!B10,UniformGrid_300_run3!B10,UniformGrid_300_run4!B10,UniformGrid_300_run5!B10) -> 0.0079672 | J11: =AVERAGE(UniformGrid_500_run1!B10,UniformGrid_500_run2!B10,UniformGrid_500_run3!B10,UniformGrid_500_run4!B10,UniformGrid_500_run5!B10) -> 0.009017 | N11: =AVERAGE(UniformGrid_100_run1!E10,UniformGrid_100_run2!E10,UniformGrid_100_run3!E10,UniformGrid_100_run4!E10,UniformGrid_100_run5!E10) -> 5.2 | O11: =AVERAGE(UniformGrid_300_run1!E10,UniformGrid_300_run2!E10,UniformGrid_300_run3!E10,UniformGrid_300_run4!E10,UniformGrid_300_run5!E10) -> 36.8 | P11: =AVERAGE(UniformGrid_500_run1!E10,UniformGrid_500_run2!E10,UniformGrid_500_run3!E10,UniformGrid_500_run4!E10,UniformGrid_500_run5!E10) -> 96
H12: =AVERAGE(UniformGrid_100_run1!B11,UniformGrid_100_run2!B11,UniformGrid_100_run3!B11,UniformGrid_100_run4!B11,UniformGrid_100_run5!B11) -> 0.0082706 | I12: =AVERAGE(UniformGrid_300_run1!B11,UniformGrid_300_run2!B11,UniformGrid_300_run3!B11,UniformGrid_300_run4!B11,UniformGrid_300_run5!B11) -> 0.007814 | J12: =AVERAGE(UniformGrid_500_run1!B11,UniformGrid_500_run2!B11,UniformGrid_500_run3!B11,UniformGrid_500_run4!B11,UniformGrid_500_run5!B11) -> 0.0088946 | N12: =AVERAGE(UniformGrid_100_run1!E11,UniformGrid_100_run2!E11,UniformGrid_100_run3!E11,UniformGrid_100_run4!E11,UniformGrid_100_run5!E11) -> 5.6 | O12: =AVERAGE(UniformGrid_300_run1!E11,UniformGrid_300_run2!E11,UniformGrid_300_run3!E11,UniformGrid_300_run4!E11,UniformGrid_300_run5!E11) -> 32.4 | P12: =AVERAGE(UniformGrid_500_run1!E11,UniformGrid_500_run2!E11,UniformGrid_500_run3!E11,UniformGrid_500_run4!E11,UniformGrid_500_run5!E11) -> 78.4
H13: =AVERAGE(UniformGrid_100_run1!B12,UniformGrid_100_run2!B12,UniformGrid_100_run3!B12,UniformGrid_100_run4!B12,UniformGrid_100_run5!B12) -> 0.0082292 | I13: =AVERAGE(UniformGrid_300_run1!B12,UniformGrid_300_run2!B12,UniformGrid_300_run3!B12,UniformGrid_300_run4!B12,UniformGrid_300_run5!B12) -> 0.0077048 | J13: =AVERAGE(UniformGrid_500_run1!B12,UniformGrid_500_run2!B12,UniformGrid_500_run3!B12,UniformGrid_500_run4!B12,UniformGrid_500_run5!B12) -> 0.010628 | N13: =AVERAGE(UniformGrid_100_run1!E12,UniformGrid_100_run2!E12,UniformGrid_100_run3!E12,UniformGrid_100_run4!E12,UniformGrid_100_run5!E12) -> 4.2 | O13: =AVERAGE(UniformGrid_300_run1!E12,UniformGrid_300_run2!E12,UniformGrid_300_run3!E12,UniformGrid_300_run4!E12,UniformGrid_300_run5!E12) -> 34.4 | P13: =AVERAGE(UniformGrid_500_run1!E12,UniformGrid_500_run2!E12,UniformGrid_500_run3!E12,UniformGrid_500_run4!E12,UniformGrid_500_run5!E12) -> 98.2
H14: =AVERAGE(UniformGrid_100_run1!B13,UniformGrid_100_run2!B13,UniformGrid_100_run3!B13,UniformGrid_100_run4!B13,UniformGrid_100_run5!B13) -> 0.0098324 | I14: =AVERAGE(UniformGrid_300_run1!B13,UniformGrid_300_run2!B13,UniformGrid_300_run3!B13,UniformGrid_300_run4!B13,UniformGrid_300_run5!B13) -> 0.0077836 | J14: =AVERAGE(UniformGrid_500_run1!B13,UniformGrid_500_run2!B13,UniformGrid_500_run3!B13,UniformGrid_500_run4!B13,UniformGrid_500_run5!B13) -> 0.0083626 | N14: =AVERAGE(UniformGrid_100_run1!E13,UniformGrid_100_run2!E13,UniformGrid_100_run3!E13,UniformGrid_100_run4!E13,UniformGrid_100_run5!E13) -> 5.2 | O14: =AVERAGE(UniformGrid_300_run1!E13,UniformGrid_300_run2!E13,UniformGrid_300_run3!E13,UniformGrid_300_run4!E13,UniformGrid_300_run5!E13) -> 31.8 | P14: =AVERAGE(UniformGrid_500_run1!E13,UniformGrid_500_run2!E13,UniformGrid_500_run3!E13,UniformGrid_500_run4!E13,UniformGrid_500_run5!E13) -> 102.8
H15: =AVERAGE(UniformGrid_100_run1!B14,UniformGrid_100_run2!B14,UniformGrid_100_run3!B14,UniformGrid_100_run4!B14,UniformGrid_100_run5!B14) -> 0.008138 | I15: =AVERAGE(UniformGrid_300_run1!B14,UniformGrid_300_run2!B14,UniformGrid_300_run3!B14,UniformGrid_300_run4!B14,UniformGrid_300_run5!B14) -> 0.0080268 | J15: =AVERAGE(UniformGrid_500_run1!B14,UniformGrid_500_run2!B14,UniformGrid_500_run3!B14,UniformGrid_500_run4!B14,UniformGrid_500_run5!B14) -> 0.0090182 | N15: =AVERAGE(UniformGrid_100_run1!E14,UniformGrid_100_run2!E14,UniformGrid_100_run3!E14,UniformGrid_100_run4!E14,UniformGrid_100_run5!E14) -> 8.6 | O15: =AVERAGE(UniformGrid_300_run1!E14,UniformGrid_300_run2!E14,UniformGrid_300_run3!E14,UniformGrid_300_run4!E14,UniformGrid_300_run5!E14) -> 30 | P15: =AVERAGE(UniformGrid_500_run1!E14,UniformGrid_500_run2!E14,UniformGrid_500_run3!E14,UniformGrid_500_run4!E14,UniformGrid_500_run5!E14) -> 90.6
H16: =AVERAGE(UniformGrid_100_run1!B15,UniformGrid_100_run2!B15,UniformGrid_100_run3!B15,UniformGrid_100_run4!B15,UniformGrid_100_run5!B15) -> 0.0083212 | I16: =AVERAGE(UniformGrid_300_run1!B15,UniformGrid_300_run2!B15,UniformGrid_300_run3!B15,UniformGrid_300_run4!B15,UniformGrid_300_run5!B15) -> 0.0079346 | J16: =AVERAGE(UniformGrid_500_run1!B15,UniformGrid_500_run2!B15,UniformGrid_500_run3!B15,UniformGrid_500_run4!B15,UniformGrid_500_run5!B15) -> 0.0086108 | N16: =AVERAGE(UniformGrid_100_run1!E15,UniformGrid_100_run2!E15,UniformGrid_100_run3!E15,UniformGrid_100_run4!E15,UniformGrid_100_run5!E15) -> 5.8 | O16: =AVERAGE(UniformGrid_300_run1!E15,UniformGrid_300_run2!E15,UniformGrid_300_run3!E15,UniformGrid_300_run4!E15,UniformGrid_300_run5!E15) -> 37.6 | P16: =AVERAGE(UniformGrid_500_run1!E15,UniformGrid_500_run2!E15,UniformGrid_500_run3!E15,UniformGrid_500_run4!E15,UniformGrid_500_run5!E15) -> 97
H17: =AVERAGE(UniformGrid_100_run1!B16,UniformGrid_100_run2!B16,UniformGrid_100_run3!B16,UniformGrid_100_run4!B16,UniformGrid_100_run5!B16) -> 0.008254 | I17: =AVERAGE(UniformGrid_300_run1!B16,UniformGrid_300_run2!B16,UniformGrid_300_run3!B16,UniformGrid_300_run4!B16,UniformGrid_300_run5!B16) -> 0.0082008 | J17: =AVERAGE(UniformGrid_500_run1!B16,UniformGrid_500_run2!B16,UniformGrid_500_run3!B16,UniformGrid_500_run4!B16,UniformGrid_500_run5!B16) -> 0.0089304 | N17: =AVERAGE(UniformGrid_100_run1!E16,UniformGrid_100_run2!E16,UniformGrid_100_run3!E16,UniformGrid_100_run4!E16,UniformGrid_100_run5!E16) -> 6.6 | O17: =AVERAGE(UniformGrid_300_run1!E16,UniformGrid_300_run2!E16,UniformGrid_300_run3!E16,UniformGrid_300_run4!E16,UniformGrid_300_run5!E16) -> 41.6 | P17: =AVERAGE(UniformGrid_500_run1!E16,UniformGrid_500_run2!E16,UniformGrid_500_run3!E16,UniformGrid_500_run4!E16,UniformGrid_500_run5!E16) -> 130.2
H18: =AVERAGE(UniformGrid_100_run1!B17,UniformGrid_100_run2!B17,UniformGrid_100_run3!B17,UniformGrid_100_run4!B17,UniformGrid_100_run5!B17) -> 0.0082804 | I18: =AVERAGE(UniformGrid_300_run1!B17,UniformGrid_300_run2!B17,UniformGrid_300_run3!B17,UniformGrid_300_run4!B17,UniformGrid_300_run5!B17) -> 0.0093822 | J18: =AVERAGE(UniformGrid_500_run1!B17,UniformGrid_500_run2!B17,UniformGrid_500_run3!B17,UniformGrid_500_run4!B17,UniformGrid_500_run5!B17) -> 0.0098568 | N18: =AVERAGE(UniformGrid_100_run1!E17,UniformGrid_100_run2!E17,UniformGrid_100_run3!E17,UniformGrid_100_run4!E17,UniformGrid_100_run5!E17) -> 8.6 | O18: =AVERAGE(UniformGrid_300_run1!E17,UniformGrid_300_run2!E17,UniformGrid_300_run3!E17,UniformGrid_300_run4!E17,UniformGrid_300_run5!E17) -> 45.8 | P18: =AVERAGE(UniformGrid_500_run1!E17,UniformGrid_500_run2!E17,UniformGrid_500_run3!E17,UniformGrid_500_run4!E17,UniformGrid_500_run5!E17) -> 102.4
H19: =AVERAGE(UniformGrid_100_run1!B18,UniformGrid_100_run2!B18,UniformGrid_100_run3!B18,UniformGrid_100_run4!B18,UniformGrid_100_run5!B18) -> 0.0095068 | I19: =AVERAGE(UniformGrid_300_run1!B18,UniformGrid_300_run2!B18,UniformGrid_300_run3!B18,UniformGrid_300_run4!B18,UniformGrid_300_run5!B18) -> 0.0082256 | J19: =AVERAGE(UniformGrid_500_run1!B18,UniformGrid_500_run2!B18,UniformGrid_500_run3!B18,UniformGrid_500_run4!B18,UniformGrid_500_run5!B18) -> 0.009411 | N19: =AVERAGE(UniformGrid_100_run1!E18,UniformGrid_100_run2!E18,UniformGrid_100_run3!E18,UniformGrid_100_run4!E18,UniformGrid_100_run5!E18) -> 9.8 | O19: =AVERAGE(UniformGrid_300_run1!E18,UniformGrid_300_run2!E18,UniformGrid_300_run3!E18,UniformGrid_300_run4!E18,UniformGrid_300_run5!E18) -> 49.2 | P19: =AVERAGE(UniformGrid_500_run1!E18,UniformGrid_500_run2!E18,UniformGrid_500_run3!E18,UniformGrid_500_run4!E18,UniformGrid_500_run5!E18) -> 105.2
H20: =AVERAGE(UniformGrid_100_run1!B19,UniformGrid_100_run2!B19,UniformGrid_100_run3!B19,UniformGrid_100_run4!B19,UniformGrid_100_run5!B19) -> 0.0096022 | I20: =AVERAGE(UniformGrid_300_run1!B19,UniformGrid_300_run2!B19,UniformGrid_300_run3!B19,UniformGrid_300_run4!B19,UniformGrid_300_run5!B19) -> 0.0076446 | J20: =AVERAGE(UniformGrid_500_run1!B19,UniformGrid_500_run2!B19,UniformGrid_500_run3!B19,UniformGrid_500_run4!B19,UniformGrid_500_run5!B19) -> 0.0079216 | N20: =AVERAGE(UniformGrid_100_run1!E19,UniformGrid_100_run2!E19,UniformGrid_100_run3!E19,UniformGrid_100_run4!E19,UniformGrid_100_run5!E19) -> 9.2 | O20: =AVERAGE(UniformGrid_300_run1!E19,UniformGrid_300_run2!E19,UniformGrid_300_run3!E19,UniformGrid_300_run4!E19,UniformGrid_300_run5!E19) -> 62.4 | P20: =AVERAGE(UniformGrid_500_run1!E19,UniformGrid_500_run2!E19,UniformGrid_500_run3!E19,UniformGrid_500_run4!E19,UniformGrid_500_run5!E19) -> 109.8
H21: =AVERAGE(UniformGrid_100_run1!B20,UniformGrid_100_run2!B20,UniformGrid_100_run3!B20,UniformGrid_100_run4!B20,UniformGrid_100_run5!B20) -> 0.0084802 | I21: =AVERAGE(UniformGrid_300_run1!B20,UniformGrid_300_run2!B20,UniformGrid_300_run3!B20,UniformGrid_300_run4!B20,UniformGrid_300_run5!B20) -> 0.0069368 | J21: =AVERAGE(UniformGrid_500_run1!B20,UniformGrid_500_run2!B20,UniformGrid_500_run3!B20,UniformGrid_500_run4!B20,UniformGrid_500_run5!B20) -> 0.0083216 | N21: =AVERAGE(UniformGrid_100_run1!E20,UniformGrid_100_run2!E20,UniformGrid_100_run3!E20,UniformGrid_100_run4!E20,UniformGrid_100_run5!E20) -> 13.4 | O21: =AVERAGE(UniformGrid_300_run1!E20,UniformGrid_300_run2!E20,UniformGrid_300_run3!E20,UniformGrid_300_run4!E20,UniformGrid_300_run5!E20) -> 55.6 | P21: =AVERAGE(UniformGrid_500_run1!E20,UniformGrid_500_run2!E20,UniformGrid_500_run3!E20,UniformGrid_500_run4!E20,UniformGrid_500_run5!E20) -> 110.4
... H802: =AVERAGE(UniformGrid_100_run1!B801,UniformGrid_100_run2!B801,UniformGrid_100_run3!B801,UniformGrid_100_run4!B801,UniformGrid_100_run5!B801) -> 0.0071602 | I802: =AVERAGE(UniformGrid_300_run1!B801,UniformGrid_300_run2!B801,UniformGrid_300_run3!B801,UniformGrid_300_run4!B801,UniformGrid_300_run5!B801) -> 0.0901448 | J802: =AVERAGE(UniformGrid_500_run1!B801,UniformGrid_500_run2!B801,UniformGrid_500_run3!B801,UniformGrid_500_run4!B801,UniformGrid_500_run5!B801) -> 0.1806294 | N802: =AVERAGE(UniformGrid_100_run1!E801,UniformGrid_100_run2!E801,UniformGrid_100_run3!E801,UniformGrid_100_run4!E801,UniformGrid_100_run5!E801) -> 324.8 | O802: =AVERAGE(UniformGrid_300_run1!E801,UniformGrid_300_run2!E801,UniformGrid_300_run3!E801,UniformGrid_300_run4!E801,UniformGrid_300_run5!E801) -> 9772.8 | P802: =AVERAGE(UniformGrid_500_run1!E801,UniformGrid_500_run2!E801,UniformGrid_500_run3!E801,UniformGrid_500_run4!E801,UniformGrid_500_run5!E801) -> 22871.4
H803: =AVERAGE(UniformGrid_100_run1!B802,UniformGrid_100_run2!B802,UniformGrid_100_run3!B802,UniformGrid_100_run4!B802,UniformGrid_100_run5!B802) -> 0.0073362 | I803: =AVERAGE(UniformGrid_300_run1!B802,UniformGrid_300_run2!B802,UniformGrid_300_run3!B802,UniformGrid_300_run4!B802,UniformGrid_300_run5!B802) -> 0.0896538 | N803: =AVERAGE(UniformGrid_100_run1!E802,UniformGrid_100_run2!E802,UniformGrid_100_run3!E802,UniformGrid_100_run4!E802,UniformGrid_100_run5!E802) -> 320.8 | O803: =AVERAGE(UniformGrid_300_run1!E802,UniformGrid_300_run2!E802,UniformGrid_300_run3!E802,UniformGrid_300_run4!E802,UniformGrid_300_run5!E802) -> 9833
H804: =AVERAGE(UniformGrid_100_run1!B803,UniformGrid_100_run2!B803,UniformGrid_100_run3!B803,UniformGrid_100_run4!B803,UniformGrid_100_run5!B803) -> 0.0075158 | I804: =AVERAGE(UniformGrid_300_run1!B803,UniformGrid_300_run2!B803,UniformGrid_300_run3!B803,UniformGrid_300_run4!B803,UniformGrid_300_run5!B803) -> 0.0902602 | N804: =AVERAGE(UniformGrid_100_run1!E803,UniformGrid_100_run2!E803,UniformGrid_100_run3!E803,UniformGrid_100_run4!E803,UniformGrid_100_run5!E803) -> 322 | O804: =AVERAGE(UniformGrid_300_run1!E803,UniformGrid_300_run2!E803,UniformGrid_300_run3!E803,UniformGrid_300_run4!E803,UniformGrid_300_run5!E803) -> 9880.6
H805: =AVERAGE(UniformGrid_100_run1!B804,UniformGrid_100_run2!B804,UniformGrid_100_run3!B804,UniformGrid_100_run4!B804,UniformGrid_100_run5!B804) -> 0.0059568 | I805: =AVERAGE(UniformGrid_300_run1!B804,UniformGrid_300_run2!B804,UniformGrid_300_run3!B804,UniformGrid_300_run4!B804,UniformGrid_300_run5!B804) -> 0.0899668 | N805: =AVERAGE(UniformGrid_100_run1!E804,UniformGrid_100_run2!E804,UniformGrid_100_run3!E804,UniformGrid_100_run4!E804,UniformGrid_100_run5!E804) -> 131.6 | O805: =AVERAGE(UniformGrid_300_run1!E804,UniformGrid_300_run2!E804,UniformGrid_300_run3!E804,UniformGrid_300_run4!E804,UniformGrid_300_run5!E804) -> 10042.4
H806: =AVERAGE(UniformGrid_100_run1!B805,UniformGrid_100_run2!B805,UniformGrid_100_run3!B805,UniformGrid_100_run4!B805,UniformGrid_100_run5!B805) -> 0.0095842 | I806: =AVERAGE(UniformGrid_300_run1!B805,UniformGrid_300_run2!B805,UniformGrid_300_run3!B805,UniformGrid_300_run4!B805,UniformGrid_300_run5!B805) -> 0.0898204 | N806: =AVERAGE(UniformGrid_100_run1!E805,UniformGrid_100_run2!E805,UniformGrid_100_run3!E805,UniformGrid_100_run4!E805,UniformGrid_100_run5!E805) -> 263 | O806: =AVERAGE(UniformGrid_300_run1!E805,UniformGrid_300_run2!E805,UniformGrid_300_run3!E805,UniformGrid_300_run4!E805,UniformGrid_300_run5!E805) -> 9997.6
H807: =AVERAGE(UniformGrid_100_run1!B806,UniformGrid_100_run2!B806,UniformGrid_100_run3!B806,UniformGrid_100_run4!B806,UniformGrid_100_run5!B806) -> 0.0085026 | I807: =AVERAGE(UniformGrid_300_run1!B806,UniformGrid_300_run2!B806,UniformGrid_300_run3!B806,UniformGrid_300_run4!B806,UniformGrid_300_run5!B806) -> 0.0901732 | N807: =AVERAGE(UniformGrid_100_run1!E806,UniformGrid_100_run2!E806,UniformGrid_100_run3!E806,UniformGrid_100_run4!E806,UniformGrid_100_run5!E806) -> 381.2 | O807: =AVERAGE(UniformGrid_300_run1!E806,UniformGrid_300_run2!E806,UniformGrid_300_run3!E806,UniformGrid_300_run4!E806,UniformGrid_300_run5!E806) -> 9912.4
H808: =AVERAGE(UniformGrid_100_run1!B807,UniformGrid_100_run2!B807,UniformGrid_100_run3!B807,UniformGrid_100_run4!B807,UniformGrid_100_run5!B807) -> 0.0080032 | I808: =AVERAGE(UniformGrid_300_run1!B807,UniformGrid_300_run2!B807,UniformGrid_300_run3!B807,UniformGrid_300_run4!B807,UniformGrid_300_run5!B807) -> 0.089754 | N808: =AVERAGE(UniformGrid_100_run1!E807,UniformGrid_100_run2!E807,UniformGrid_100_run3!E807,UniformGrid_100_run4!E807,UniformGrid_100_run5!E807) -> 383.8 | O808: =AVERAGE(UniformGrid_300_run1!E807,UniformGrid_300_run2!E807,UniformGrid_300_run3!E807,UniformGrid_300_run4!E807,UniformGrid_300_run5!E807) -> 9965.2
H809: =AVERAGE(UniformGrid_100_run1!B808,UniformGrid_100_run2!B808,UniformGrid_100_run3!B808,UniformGrid_100_run4!B808,UniformGrid_100_run5!B808) -> 0.0063022 | I809: =AVERAGE(UniformGrid_300_run1!B808,UniformGrid_300_run2!B808,UniformGrid_300_run3!B808,UniformGrid_300_run4!B808,UniformGrid_300_run5!B808) -> 0.0896928 | N809: =AVERAGE(UniformGrid_100_run1!E808,UniformGrid_100_run2!E808,UniformGrid_100_run3!E808,UniformGrid_100_run4!E808,UniformGrid_100_run5!E808) -> 197.2 | O809: =AVERAGE(UniformGrid_300_run1!E808,UniformGrid_300_run2!E808,UniformGrid_300_run3!E808,UniformGrid_300_run4!E808,UniformGrid_300_run5!E808) -> 9999.2
H810: =AVERAGE(UniformGrid_100_run1!B809,UniformGrid_100_run2!B809,UniformGrid_100_run3!B809,UniformGrid_100_run4!B809,UniformGrid_100_run5!B809) -> 0.0078652 | I810: =AVERAGE(UniformGrid_300_run1!B809,UniformGrid_300_run2!B809,UniformGrid_300_run3!B809,UniformGrid_300_run4!B809,UniformGrid_300_run5!B809) -> 0.0897326 | N810: =AVERAGE(UniformGrid_100_run1!E809,UniformGrid_100_run2!E809,UniformGrid_100_run3!E809,UniformGrid_100_run4!E809,UniformGrid_100_run5!E809) -> 316.2 | O810: =AVERAGE(UniformGrid_300_run1!E809,UniformGrid_300_run2!E809,UniformGrid_300_run3!E809,UniformGrid_300_run4!E809,UniformGrid_300_run5!E809) -> 9934.2
H811: =AVERAGE(UniformGrid_100_run1!B810,UniformGrid_100_run2!B810,UniformGrid_100_run3!B810,UniformGrid_100_run4!B810,UniformGrid_100_run5!B810) -> 0.0078992 | I811: =AVERAGE(UniformGrid_300_run1!B810,UniformGrid_300_run2!B810,UniformGrid_300_run3!B810,UniformGrid_300_run4!B810,UniformGrid_300_run5!B810) -> 0.0902438 | N811: =AVERAGE(UniformGrid_100_run1!E810,UniformGrid_100_run2!E810,UniformGrid_100_run3!E810,UniformGrid_100_run4!E810,UniformGrid_100_run5!E810) -> 312.6 | O811: =AVERAGE(UniformGrid_300_run1!E810,UniformGrid_300_run2!E810,UniformGrid_300_run3!E810,UniformGrid_300_run4!E810,UniformGrid_300_run5!E810) -> 10044.8
H812: =AVERAGE(UniformGrid_100_run1!B811,UniformGrid_100_run2!B811,UniformGrid_100_run3!B811,UniformGrid_100_run4!B811,UniformGrid_100_run5!B811) -> 0.0063668 | I812: =AVERAGE(UniformGrid_300_run1!B811,UniformGrid_300_run2!B811,UniformGrid_300_run3!B811,UniformGrid_300_run4!B811,UniformGrid_300_run5!B811) -> 0.0896482 | N812: =AVERAGE(UniformGrid_100_run1!E811,UniformGrid_100_run2!E811,UniformGrid_100_run3!E811,UniformGrid_100_run4!E811,UniformGrid_100_run5!E811) -> 181 | O812: =AVERAGE(UniformGrid_300_run1!E811,UniformGrid_300_run2!E811,UniformGrid_300_run3!E811,UniformGrid_300_run4!E811,UniformGrid_300_run5!E811) -> 10020.2
